Workbook

Sheet Parameters
A1: Type | B1: Pi_prim | C1: Pi_sec | D1: Phi_type | E1: r_type
A2: Spot | B2: 0.4 | C2: =1-B2 -> 0.6 | D2: 0.35 | E2: 0.03
A3: Perps | B3: 0.3 | C3: =1-B3 -> 0.7 | D3: 0.5 | E3: 0.05
A4: RWA | B4: 0.2 | C4: =1-B4 -> 0.8 | D4: 0.3 | E4: 0.05
A5: RE | B5: 0 | C5: =1-B5 -> 1 | D5: 0.25 | E5: 0.03
A9: Phase | B9: Layer | C9: Pi_prim | D9: Pi_sec | E9: Phi_layer | F9: r_layer | H9: Phase | I9: w_H | J9: wₙ (Native Usage) | K9: δ (Discount Rate) | L9: multiplier
A10: P0 | B10: L1 | C10: =B2*'GMV(Layer)'!Q2 -> 0.4 | D10: =1-표1[[#This Row],[Pi_prim]] -> 0.6 | E10: =D2*'GMV(Layer)'!Q2+D3*'GMV(Layer)'!R2+D4*'GMV(Layer)'!S2+D5*'GMV(Layer)'!T2 -> 0.35 | F10: =E2*'GMV(Layer)'!Q2+E3*'GMV(Layer)'!R2+E4*'GMV(Layer)'!S2+E5*'GMV(Layer)'!T2 -> 0.03 | H10: P0 | I10: =1-표2[[#This Row],[wₙ (Native Usage)]] -> 1 | J10: 0 | K10: 0.2 | L10: =1-표2[[#This Row],[wₙ (Native Usage)]]*표2[[#This Row],[δ (Discount Rate)]] -> 1
B11: L2 | C11: =B2*'GMV(Layer)'!Q3 -> 0.4 | D11: =1-표1[[#This Row],[Pi_prim]] -> 0.6 | E11: =D2*'GMV(Layer)'!Q3+D3*'GMV(Layer)'!R3+D4*'GMV(Layer)'!S3+D5*'GMV(Layer)'!T3 -> 0.35 | F11: =E2*'GMV(Layer)'!Q3+E3*'GMV(Layer)'!R3+E4*'GMV(Layer)'!S3+E5*'GMV(Layer)'!T3 -> 0.03 | H11: P1 | I11: =1-표2[[#This Row],[wₙ (Native Usage)]] -> 0.85 | J11: 0.15 | K11: =K10 -> 0.2 | L11: =1-표2[[#This Row],[wₙ (Native Usage)]]*표2[[#This Row],[δ (Discount Rate)]] -> 0.97
B12: VS | C12: =B2*'GMV(Layer)'!Q4 -> 0.4 | D12: =1-표1[[#This Row],[Pi_prim]] -> 0.6 | E12: =D2*'GMV(Layer)'!Q4+D3*'GMV(Layer)'!R4+D4*'GMV(Layer)'!S4+D5*'GMV(Layer)'!T4 -> 0.35 | F12: 0.7 | H12: P2 | I12: =1-표2[[#This Row],[wₙ (Native Usage)]] -> 0.75 | J12: 0.25 | K12: =K11 -> 0.2 | L12: =1-표2[[#This Row],[wₙ (Native Usage)]]*표2[[#This Row],[δ (Discount Rate)]] -> 0.95
B13: Partner | C13: 0 | D13: =1-표1[[#This Row],[Pi_prim]] -> 1 | E13: 0 | F13: - | H13: P3 | I13: =1-표2[[#This Row],[wₙ (Native Usage)]] -> 0.65 | J13: 0.35 | K13: =K12 -> 0.2 | L13: =1-표2[[#This Row],[wₙ (Native Usage)]]*표2[[#This Row],[δ (Discount Rate)]] -> 0.93
B14: L3 | C14: 0 | D14: =1-표1[[#This Row],[Pi_prim]] -> 1 | E14: 0 | F14: - | H14: P4 | I14: =1-표2[[#This Row],[wₙ (Native Usage)]] -> 0.55 | J14: 0.45 | K14: =K13 -> 0.2 | L14: =1-표2[[#This Row],[wₙ (Native Usage)]]*표2[[#This Row],[δ (Discount Rate)]] -> 0.91
A15: P1 | B15: L1 | C15: =B2*'GMV(Layer)'!Q7 -> 0.4 | D15: =1-표1[[#This Row],[Pi_prim]] -> 0.6 | E15: =D2*'GMV(Layer)'!Q7+D3*'GMV(Layer)'!R7+D4*'GMV(Layer)'!S7+D5*'GMV(Layer)'!T7 -> 0.35 | F15: =E2*'GMV(Layer)'!Q7+E3*'GMV(Layer)'!R7+E4*'GMV(Layer)'!S7+E5*'GMV(Layer)'!T7 -> 0.03 | H15: P5 | I15: =1-표2[[#This Row],[wₙ (Native Usage)]] -> 0.4 | J15: 0.6 | K15: =K14 -> 0.2 | L15: =1-표2[[#This Row],[wₙ (Native Usage)]]*표2[[#This Row],[δ (Discount Rate)]] -> 0.88
B16: L2 | C16: =B2*'GMV(Layer)'!Q8 -> 0.4 | D16: =1-표1[[#This Row],[Pi_prim]] -> 0.6 | E16: =D2*'GMV(Layer)'!Q8+D3*'GMV(Layer)'!R8+D4*'GMV(Layer)'!S8+D5*'GMV(Layer)'!T8 -> 0.35 | F16: =E2*'GMV(Layer)'!Q8+E3*'GMV(Layer)'!R8+E4*'GMV(Layer)'!S8+E5*'GMV(Layer)'!T8 -> 0.03
B17: VS | C17: =B2*'GMV(Layer)'!Q9 -> 0.4 | D17: =1-표1[[#This Row],[Pi_prim]] -> 0.6 | E17: =D2*'GMV(Layer)'!Q9+D3*'GMV(Layer)'!R9+D4*'GMV(Layer)'!S9+D5*'GMV(Layer)'!T9 -> 0.35 | F17: =F12 -> 0.7
B18: Partner | C18: 0 | D18: =1-표1[[#This Row],[Pi_prim]] -> 1 | E18: 0 | F18: -
B19: L3 | C19: 0 | D19: =1-표1[[#This Row],[Pi_prim]] -> 1 | E19: 0 | F19: -
A20: P2 | B20: L1 | C20: =B2*'GMV(Layer)'!Q12+B3*'GMV(Layer)'!R12+B4*'GMV(Layer)'!S12+B5*'GMV(Layer)'!T12 -> 0.37 | D20: =1-표1[[#This Row],[Pi_prim]] -> 0.63 | E20: =D2*'GMV(Layer)'!Q12+D3*'GMV(Layer)'!R12+D4*'GMV(Layer)'!S12+D5*'GMV(Layer)'!T12 -> 0.395 | F20: =E2*'GMV(Layer)'!Q12+E3*'GMV(Layer)'!R12+E4*'GMV(Layer)'!S12+E5*'GMV(Layer)'!T12 -> 0.036 | H20: $HYPE in USD | I20: $HIDE in USD | J20: $HIIN in USD
B21: L2 | C21: =B2*'GMV(Layer)'!Q13+B3*'GMV(Layer)'!R13+B4*'GMV(Layer)'!S13+B5*'GMV(Layer)'!T13 -> 0.37 | D21: =1-표1[[#This Row],[Pi_prim]] -> 0.63 | E21: =D2*'GMV(Layer)'!Q13+D3*'GMV(Layer)'!R13+D4*'GMV(Layer)'!S13+D5*'GMV(Layer)'!T13 -> 0.395 | F21: =E2*'GMV(Layer)'!Q13+E3*'GMV(Layer)'!R13+E4*'GMV(Layer)'!S13+E5*'GMV(Layer)'!T13 -> 0.036 | H21: 40 | I21: 0.0002 | J21: 0.0004
B22: VS | C22: =B2*'GMV(Layer)'!Q14+B3*'GMV(Layer)'!R14+B4*'GMV(Layer)'!S14+B5*'GMV(Layer)'!T14 -> 0.37 | D22: =1-표1[[#This Row],[Pi_prim]] -> 0.63 | E22: =D2*'GMV(Layer)'!Q14+D3*'GMV(Layer)'!R14+D4*'GMV(Layer)'!S14+D5*'GMV(Layer)'!T14 -> 0.395 | F22: =F12 -> 0.7
B23: Partner | C23: 0 | D23: =1-표1[[#This Row],[Pi_prim]] -> 1 | E23: 0 | F23: - | H23: USD in $HYPE | I23: USD in $HIDE | J23: USD in $HIIN
B24: L3 | C24: 0 | D24: =1-표1[[#This Row],[Pi_prim]] -> 1 | E24: 0 | F24: - | H24: {=1/표5[$HYPE in USD]} -> 0.025 | I24: {=1/표5[$HIDE in USD]} -> 5000 | J24: {=1/표5[$HIIN in USD]} -> 2500
A25: P3 | B25: L1 | C25: =B2*'GMV(Layer)'!Q17+B3*'GMV(Layer)'!R17+B4*'GMV(Layer)'!S17+B5*'GMV(Layer)'!T17 -> 0.345 | D25: =1-표1[[#This Row],[Pi_prim]] -> 0.655 | E25: =D2*'GMV(Layer)'!Q17+D3*'GMV(Layer)'!R17+D4*'GMV(Layer)'!S17+D5*'GMV(Layer)'!T17 -> 0.3975 | F25: =E2*'GMV(Layer)'!Q17+E3*'GMV(Layer)'!R17+E4*'GMV(Layer)'!S17+E5*'GMV(Layer)'!T17 -> 0.039
B26: L2 | C26: =B2*'GMV(Layer)'!Q18+B3*'GMV(Layer)'!R18+B4*'GMV(Layer)'!S18+B5*'GMV(Layer)'!T18 -> 0.345 | D26: =1-표1[[#This Row],[Pi_prim]] -> 0.655 | E26: =D2*'GMV(Layer)'!Q18+D3*'GMV(Layer)'!R18+D4*'GMV(Layer)'!S18+D5*'GMV(Layer)'!T18 -> 0.3975 | F26: =E2*'GMV(Layer)'!Q18+E3*'GMV(Layer)'!R18+E4*'GMV(Layer)'!S18+E5*'GMV(Layer)'!T18 -> 0.039
B27: VS | C27: =B2*'GMV(Layer)'!Q19+B3*'GMV(Layer)'!R19+B4*'GMV(Layer)'!S19+B5*'GMV(Layer)'!T19 -> 0.345 | D27: =1-표1[[#This Row],[Pi_prim]] -> 0.655 | E27: =D2*'GMV(Layer)'!Q19+D3*'GMV(Layer)'!R19+D4*'GMV(Layer)'!S19+D5*'GMV(Layer)'!T19 -> 0.3975 | F27: =F12 -> 0.7
B28: Partner | C28: 0 | D28: =1-표1[[#This Row],[Pi_prim]] -> 1 | E28: 0 | F28: -
B29: L3 | C29: 0 | D29: =1-표1[[#This Row],[Pi_prim]] -> 1 | E29: 0 | F29: -
A30: P4 | B30: L1 | C30: =B2*'GMV(Layer)'!Q22+B3*'GMV(Layer)'!R22+B4*'GMV(Layer)'!S22+B5*'GMV(Layer)'!T22 -> 0.32 | D30: =1-표1[[#This Row],[Pi_prim]] -> 0.68 | E30: =D2*'GMV(Layer)'!Q22+D3*'GMV(Layer)'!R22+D4*'GMV(Layer)'!S22+D5*'GMV(Layer)'!T22 -> 0.4 | F30: =E2*'GMV(Layer)'!Q22+E3*'GMV(Layer)'!R22+E4*'GMV(Layer)'!S22+E5*'GMV(Layer)'!T22 -> 0.042
B31: L2 | C31: =B2*'GMV(Layer)'!Q23+B3*'GMV(Layer)'!R23+B4*'GMV(Layer)'!S23+B5*'GMV(Layer)'!T23 -> 0.32 | D31: =1-표1[[#This Row],[Pi_prim]] -> 0.68 | E31: =D2*'GMV(Layer)'!Q23+D3*'GMV(Layer)'!R23+D4*'GMV(Layer)'!S23+D5*'GMV(Layer)'!T23 -> 0.4 | F31: =E2*'GMV(Layer)'!Q23+E3*'GMV(Layer)'!R23+E4*'GMV(Layer)'!S23+E5*'GMV(Layer)'!T23 -> 0.042
B32: VS | C32: =B2*'GMV(Layer)'!Q24+B3*'GMV(Layer)'!R24+B4*'GMV(Layer)'!S24+B5*'GMV(Layer)'!T24 -> 0.32 | D32: =1-표1[[#This Row],[Pi_prim]] -> 0.68 | E32: =D2*'GMV(Layer)'!Q24+D3*'GMV(Layer)'!R24+D4*'GMV(Layer)'!S24+D5*'GMV(Layer)'!T24 -> 0.4 | F32: =F12 -> 0.7
B33: Partner | C33: 0 | D33: =1-표1[[#This Row],[Pi_prim]] -> 1 | E33: 0 | F33: -
B34: L3 | C34: 0 | D34: =1-표1[[#This Row],[Pi_prim]] -> 1 | E34: 0 | F34: -
A35: P5 | B35: L1 | C35: =B2*'GMV(Layer)'!Q27+B3*'GMV(Layer)'!R27+B4*'GMV(Layer)'!S27+B5*'GMV(Layer)'!T27 -> 0.265 | D35: =1-표1[[#This Row],[Pi_prim]] -> 0.735 | E35: =D2*'GMV(Layer)'!Q27+D3*'GMV(Layer)'!R27+D4*'GMV(Layer)'!S27+D5*'GMV(Layer)'!T27 -> 0.3775 | F35: =E2*'GMV(Layer)'!Q27+E3*'GMV(Layer)'!R27+E4*'GMV(Layer)'!S27+E5*'GMV(Layer)'!T27 -> 0.041
B36: L2 | C36: =B2*'GMV(Layer)'!Q28+B3*'GMV(Layer)'!R28+B4*'GMV(Layer)'!S28+B5*'GMV(Layer)'!T28 -> 0.31176471 | D36: =1-표1[[#This Row],[Pi_prim]] -> 0.68823529 | E36: =D2*'GMV(Layer)'!Q28+D3*'GMV(Layer)'!R28+D4*'GMV(Layer)'!S28+D5*'GMV(Layer)'!T28 -> 0.4 | F36: =E2*'GMV(Layer)'!Q28+E3*'GMV(Layer)'!R28+E4*'GMV(Layer)'!S28+E5*'GMV(Layer)'!T28 -> 0.042941176
B37: VS | C37: =B2*'GMV(Layer)'!Q29+B3*'GMV(Layer)'!R29+B4*'GMV(Layer)'!S29+B5*'GMV(Layer)'!T29 -> 0.31176471 | D37: =1-표1[[#This Row],[Pi_prim]] -> 0.68823529 | E37: =D2*'GMV(Layer)'!Q29+D3*'GMV(Layer)'!R29+D4*'GMV(Layer)'!S29+D5*'GMV(Layer)'!T29 -> 0.4 | F37: =F12 -> 0.7
B38: Partner | C38: 0 | D38: =1-표1[[#This Row],[Pi_prim]] -> 1 | E38: 0 | F38: -
B39: L3 | C39: 0 | D39: =1-표1[[#This Row],[Pi_prim]] -> 1 | E39: 0 | F39: -

Sheet GMV(Total)
A1: Phase | B1: m_k(months) | C1: φ (User) | D1: ψ (Repeat) | E1: χ (Partner) | F1: F_k = φ×ψ×χ | G1: g_k (monthly) | H1: GMV_start (B) | I1: GMV_end (B) | J1: GMV_avg (B) | K1: Total F (product)
A2: P0 | B2: 2 | C2: N/A | D2: N/A | E2: N/A | F2: N/A | G2: N/A | H2: N/A | I2: =I3/F3 -> 0.20260943 | K2: =PRODUCT(F2:F7) -> 21.384
A3: P1 | B3: 2 | C3: 1.4 | D3: 1.2 | E3: 1.2 | F3: 2 | G3: =F3^(1/B3)-1 -> 0.41421356 | H3: =I3/F3 -> 0.20260943 | I3: =I4/F4 -> 0.40521886 | J3: =I3/SQRT(F3) -> 0.286533
A4: P2 | B4: 6 | C4: 1.5 | D4: 1.3 | E4: 1.5 | F4: 3.3 | G4: =F4^(1/B4)-1 -> 0.2201662 | H4: =I4/F4 -> 0.40521886 | I4: =I5/F5 -> 1.3372222 | J4: =I4/SQRT(F4) -> 0.73611661
A5: P3 | B5: 6 | C5: 1.2 | D5: 1.1 | E5: 1.3 | F5: 1.8 | G5: =F5^(1/B5)-1 -> 0.10292357 | H5: =I5/F5 -> 1.3372222 | I5: =I6/F6 -> 2.407 | J5: =I5/SQRT(F5) -> 1.7940719
A6: P4 | B6: 6 | C6: 1.1 | D6: 1.1 | E6: 1.2 | F6: 1.5 | G6: =F6^(1/B6)-1 -> 0.069913194 | H6: =I6/F6 -> 2.407 | I6: =I7/F7 -> 3.6105 | J6: =I6/SQRT(F6) -> 2.9479609
A7: P5 | B7: 6 | C7: 1.05 | D7: 1.05 | E7: 1.1 | F7: 1.2 | G7: =F7^(1/B7)-1 -> 0.030853321 | H7: =I7/F7 -> 3.6105 | I7: =9.628*45% -> 4.3326 | J7: =I7/SQRT(F7) -> 3.9551046

Sheet GMV(Layer)
A1: Phase | B1: Layer | C1: α_ℓ^(p) (Layer share) | D1: β_Spot^(p) | E1: β_Perps^(p) | F1: β_RWA^(p) | G1: β_RE^(p) | H1: m_(ℓ,Spot) | I1: m_(ℓ,Perps) | J1: m_(ℓ,RWA) | K1: m_(ℓ,RE) | L1: score_Spot | M1: score_Perps | N1: score_RWA | O1: score_RE | P1: score_sum | Q1: w_Spot | R1: w_Perps | S1: w_RWA | T1: w_RE | U1: GMV_total^(p) (Phase별 평균 GMV) | V1: GMV_layer = α·GMV_total | W1: GMV_(ℓ,Spot) | X1: GMV_(ℓ,Perps) | Y1: GMV_(ℓ,RWA) | Z1: GMV_(ℓ,RE) | AA1: Vprim(B) | AB1: Vsec(B) | AC1: GMV_trade
A2: P0 | B2: L1 | C2: 0.05 | D2: 1 | E2: 0 | F2: 0 | G2: 0 | H2: 1 | I2: 0 | J2: 0 | K2: 0 | L2: =D2 * C2 * H2 -> 0.05 | M2: =E2 * C2 * I2 -> 0 | N2: =F2 * C2 * J2 -> 0 | O2: =G2 * C2 * K2 -> 0 | P2: =L2 + M2 + N2 + O2 -> 0.05 | Q2: =IF($P2=0, 0, L2 / $P2) -> 1 | R2: =IF($P2=0, 0, M2 / $P2) -> 0 | S2: =IF($P2=0, 0, N2 / $P2) -> 0 | T2: =IF($P2=0, 0, O2 / $P2) -> 0 | U2: ='GMV(Total)'!I2 -> 0.20260943 | V2: =C2 * U2 -> 0.010130471 | W2: =Q2 * V2 -> 0.010130471 | X2: =R2 * V2 -> 0 | Y2: =S2 * V2 -> 0 | Z2: =T2 * V2 -> 0 | AA2: =V2*Parameters!C10 -> 0.0040521886 | AB2: =V2*Parameters!D10 -> 0.0060782828 | AC2: =V2-AUM!O2 -> 0.0099592521
B3: L2 | C3: 0.1 | D3: 1 | E3: 0 | F3: 0 | G3: 0 | H3: 1 | I3: 0 | J3: 0 | K3: 0 | L3: =D3 * C3 * H3 -> 0.1 | M3: =E3 * C3 * I3 -> 0 | N3: =F3 * C3 * J3 -> 0 | O3: =G3 * C3 * K3 -> 0 | P3: =L3 + M3 + N3 + O3 -> 0.1 | Q3: =IF($P3=0, 0, L3 / $P3) -> 1 | R3: =IF($P3=0, 0, M3 / $P3) -> 0 | S3: =IF($P3=0, 0, N3 / $P3) -> 0 | T3: =IF($P3=0, 0, O3 / $P3) -> 0 | U3: ='GMV(Total)'!I2 -> 0.20260943 | V3: =C3 * U3 -> 0.020260943 | W3: =Q3 * V3 -> 0.020260943 | X3: =R3 * V3 -> 0 | Y3: =S3 * V3 -> 0 | Z3: =T3 * V3 -> 0 | AA3: =V3*Parameters!C11 -> 0.0081043771 | AB3: =V3*Parameters!D11 -> 0.012156566 | AC3: =V3-AUM!O3 -> 0.019794762 | AE3: Phase | AF3: GMV_trade(B) | AG3: GMV_noncanonical | AH3: GMV_Canonical
B4: VS | C4: 0 | D4: 1 | E4: 0 | F4: 0 | G4: 0 | H4: 1 | I4: 0 | J4: 0 | K4: 0 | L4: =D4 * C4 * H4 -> 0 | M4: =E4 * C4 * I4 -> 0 | N4: =F4 * C4 * J4 -> 0 | O4: =G4 * C4 * K4 -> 0 | P4: =L4 + M4 + N4 + O4 -> 0 | Q4: 1 | R4: =IF($P4=0, 0, M4 / $P4) -> 0 | S4: =IF($P4=0, 0, N4 / $P4) -> 0 | T4: =IF($P4=0, 0, O4 / $P4) -> 0 | U4: ='GMV(Total)'!I2 -> 0.20260943 | V4: =C4 * U4 -> 0 | W4: =Q4 * V4 -> 0 | X4: =R4 * V4 -> 0 | Y4: =S4 * V4 -> 0 | Z4: =T4 * V4 -> 0 | AA4: =V4*Parameters!C12 -> 0 | AB4: =V4*Parameters!D12 -> 0 | AC4: =V4-AUM!O4 -> 0 | AE4: P0 | AF4: =SUM(AC2:AC6) -> 0.20197203 | AG4: =표4[[#This Row],[GMV_trade(B)]]-표4[[#This Row],[GMV_Canonical]] -> 0.20197203 | AH4: =AC3*'Launch Fee'!I2 -> 0
B5: Partner | C5: 0.35 | D5: 1 | E5: 0 | F5: 0 | G5: 0 | H5: 1 | I5: 0 | J5: 0 | K5: 0 | L5: =D5 * C5 * H5 -> 0.35 | M5: =E5 * C5 * I5 -> 0 | N5: =F5 * C5 * J5 -> 0 | O5: =G5 * C5 * K5 -> 0 | P5: =L5 + M5 + N5 + O5 -> 0.35 | Q5: =IF($P5=0, 0, L5 / $P5) -> 1 | R5: =IF($P5=0, 0, M5 / $P5) -> 0 | S5: =IF($P5=0, 0, N5 / $P5) -> 0 | T5: =IF($P5=0, 0, O5 / $P5) -> 0 | U5: ='GMV(Total)'!I2 -> 0.20260943 | V5: =C5 * U5 -> 0.0709133 | W5: =Q5 * V5 -> 0.0709133 | X5: =R5 * V5 -> 0 | Y5: =S5 * V5 -> 0 | Z5: =T5 * V5 -> 0 | AA5: =V5*Parameters!C13 -> 0 | AB5: =V5*Parameters!D13 -> 0.0709133 | AC5: =V5-AUM!O5 -> 0.0709133 | AE5: P1 | AF5: =SUM(AC7:AC11) -> 0.40085557 | AG5: =표4[[#This Row],[GMV_trade(B)]]-표4[[#This Row],[GMV_Canonical]] -> 0.40036071 | AH5: =AC8*'Launch Fee'!I3 -> 0.00049486904
B6: L3 | C6: 0.5 | D6: 1 | E6: 0 | F6: 0 | G6: 0 | H6: 1 | I6: 0 | J6: 0 | K6: 0 | L6: =D6 * C6 * H6 -> 0.5 | M6: =E6 * C6 * I6 -> 0 | N6: =F6 * C6 * J6 -> 0 | O6: =G6 * C6 * K6 -> 0 | P6: =L6 + M6 + N6 + O6 -> 0.5 | Q6: =IF($P6=0, 0, L6 / $P6) -> 1 | R6: =IF($P6=0, 0, M6 / $P6) -> 0 | S6: =IF($P6=0, 0, N6 / $P6) -> 0 | T6: =IF($P6=0, 0, O6 / $P6) -> 0 | U6: ='GMV(Total)'!I2 -> 0.20260943 | V6: =C6 * U6 -> 0.10130471 | W6: =Q6 * V6 -> 0.10130471 | X6: =R6 * V6 -> 0 | Y6: =S6 * V6 -> 0 | Z6: =T6 * V6 -> 0 | AA6: =V6*Parameters!C14 -> 0 | AB6: =V6*Parameters!D14 -> 0.10130471 | AC6: =V6-AUM!O6 -> 0.10130471 | AE6: P2 | AF6: =SUM(AC12:AC16) -> 1.3198446 | AG6: =표4[[#This Row],[GMV_trade(B)]]-표4[[#This Row],[GMV_Canonical]] -> 1.3169142 | AH6: =AC13*'Launch Fee'!I4 -> 0.0029304292
A7: P1 | B7: L1 | C7: 0.2 | D7: 1 | E7: 0 | F7: 0 | G7: 0 | H7: 1 | I7: 0 | J7: 0 | K7: 0 | L7: =D7 * C7 * H7 -> 0.2 | M7: =E7 * C7 * I7 -> 0 | N7: =F7 * C7 * J7 -> 0 | O7: =G7 * C7 * K7 -> 0 | P7: =L7 + M7 + N7 + O7 -> 0.2 | Q7: =IF($P7=0, 0, L7 / $P7) -> 1 | R7: =IF($P7=0, 0, M7 / $P7) -> 0 | S7: =IF($P7=0, 0, N7 / $P7) -> 0 | T7: =IF($P7=0, 0, O7 / $P7) -> 0 | U7: ='GMV(Total)'!I3 -> 0.40521886 | V7: =C7 * U7 -> 0.081043771 | W7: =Q7 * V7 -> 0.081043771 | X7: =R7 * V7 -> 0 | Y7: =S7 * V7 -> 0 | Z7: =T7 * V7 -> 0 | AA7: =V7*Parameters!C15 -> 0.032417508 | AB7: =V7*Parameters!D15 -> 0.048626263 | AC7: =V7-AUM!O7 -> 0.079674017 | AE7: P3 | AF7: =SUM(AC17:AC21) -> 2.3735856 | AG7: =표4[[#This Row],[GMV_trade(B)]]-표4[[#This Row],[GMV_Canonical]] -> 2.3669852 | AH7: =AC18*'Launch Fee'!I5 -> 0.0066004033
B8: L2 | C8: 0.25 | D8: 1 | E8: 0 | F8: 0 | G8: 0 | H8: 1 | I8: 0 | J8: 0 | K8: 0 | L8: =D8 * C8 * H8 -> 0.25 | M8: =E8 * C8 * I8 -> 0 | N8: =F8 * C8 * J8 -> 0 | O8: =G8 * C8 * K8 -> 0 | P8: =L8 + M8 + N8 + O8 -> 0.25 | Q8: =IF($P8=0, 0, L8 / $P8) -> 1 | R8: =IF($P8=0, 0, M8 / $P8) -> 0 | S8: =IF($P8=0, 0, N8 / $P8) -> 0 | T8: =IF($P8=0, 0, O8 / $P8) -> 0 | U8: ='GMV(Total)'!I3 -> 0.40521886 | V8: =C8 * U8 -> 0.10130471 | W8: =Q8 * V8 -> 0.10130471 | X8: =R8 * V8 -> 0 | Y8: =S8 * V8 -> 0 | Z8: =T8 * V8 -> 0 | AA8: =V8*Parameters!C16 -> 0.040521886 | AB8: =V8*Parameters!D16 -> 0.060782828 | AC8: =V8-AUM!O8 -> 0.098973809 | AE8: P4 | AF8: =SUM(AC22:AC26) -> 3.5579926 | AG8: =표4[[#This Row],[GMV_trade(B)]]-표4[[#This Row],[GMV_Canonical]] -> 3.5460981 | AH8: =AC23*'Launch Fee'!I6 -> 0.011894509
B9: VS | C9: 0.05 | D9: 1 | E9: 0 | F9: 0 | G9: 0 | H9: 1 | I9: 0 | J9: 0 | K9: 0 | L9: =D9 * C9 * H9 -> 0.05 | M9: =E9 * C9 * I9 -> 0 | N9: =F9 * C9 * J9 -> 0 | O9: =G9 * C9 * K9 -> 0 | P9: =L9 + M9 + N9 + O9 -> 0.05 | Q9: =IF($P9=0, 0, L9 / $P9) -> 1 | R9: =IF($P9=0, 0, M9 / $P9) -> 0 | S9: =IF($P9=0, 0, N9 / $P9) -> 0 | T9: =IF($P9=0, 0, O9 / $P9) -> 0 | U9: ='GMV(Total)'!I3 -> 0.40521886 | V9: =C9 * U9 -> 0.020260943 | W9: =Q9 * V9 -> 0.020260943 | X9: =R9 * V9 -> 0 | Y9: =S9 * V9 -> 0 | Z9: =T9 * V9 -> 0 | AA9: =V9*Parameters!C17 -> 0.0081043771 | AB9: =V9*Parameters!D17 -> 0.012156566 | AC9: =V9-AUM!O9 -> 0.019598321 | AE9: P5 | AF9: =SUM(AC27:AC31) -> 4.2718164 | AG9: =표4[[#This Row],[GMV_trade(B)]]-표4[[#This Row],[GMV_Canonical]] -> 4.2551574 | AH9: =AC28*'Launch Fee'!I7 -> 0.016658934
B10: Partner | C10: 0.25 | D10: 1 | E10: 0 | F10: 0 | G10: 0 | H10: 1 | I10: 0 | J10: 0 | K10: 0 | L10: =D10 * C10 * H10 -> 0.25 | M10: =E10 * C10 * I10 -> 0 | N10: =F10 * C10 * J10 -> 0 | O10: =G10 * C10 * K10 -> 0 | P10: =L10 + M10 + N10 + O10 -> 0.25 | Q10: =IF($P10=0, 0, L10 / $P10) -> 1 | R10: =IF($P10=0, 0, M10 / $P10) -> 0 | S10: =IF($P10=0, 0, N10 / $P10) -> 0 | T10: =IF($P10=0, 0, O10 / $P10) -> 0 | U10: ='GMV(Total)'!I3 -> 0.40521886 | V10: =C10 * U10 -> 0.10130471 | W10: =Q10 * V10 -> 0.10130471 | X10: =R10 * V10 -> 0 | Y10: =S10 * V10 -> 0 | Z10: =T10 * V10 -> 0 | AA10: =V10*Parameters!C18 -> 0 | AB10: =V10*Parameters!D18 -> 0.10130471 | AC10: =V10-AUM!O10 -> 0.10130471
B11: L3 | C11: 0.25 | D11: 1 | E11: 0 | F11: 0 | G11: 0 | H11: 1 | I11: 0 | J11: 0 | K11: 0 | L11: =D11 * C11 * H11 -> 0.25 | M11: =E11 * C11 * I11 -> 0 | N11: =F11 * C11 * J11 -> 0 | O11: =G11 * C11 * K11 -> 0 | P11: =L11 + M11 + N11 + O11 -> 0.25 | Q11: =IF($P11=0, 0, L11 / $P11) -> 1 | R11: =IF($P11=0, 0, M11 / $P11) -> 0 | S11: =IF($P11=0, 0, N11 / $P11) -> 0 | T11: =IF($P11=0, 0, O11 / $P11) -> 0 | U11: ='GMV(Total)'!I3 -> 0.40521886 | V11: =C11 * U11 -> 0.10130471 | W11: =Q11 * V11 -> 0.10130471 | X11: =R11 * V11 -> 0 | Y11: =S11 * V11 -> 0 | Z11: =T11 * V11 -> 0 | AA11: =V11*Parameters!C19 -> 0 | AB11: =V11*Parameters!D19 -> 0.10130471 | AC11: =V11-AUM!O11 -> 0.10130471
A12: P2 | B12: L1 | C12: 0.28 | D12: 0.7 | E12: 0.3 | F12: 0 | G12: 0 | H12: 1 | I12: 1 | J12: 0 | K12: 0 | L12: =D12 * C12 * H12 -> 0.196 | M12: =E12 * C12 * I12 -> 0.084 | N12: =F12 * C12 * J12 -> 0 | O12: =G12 * C12 * K12 -> 0 | P12: =L12 + M12 + N12 + O12 -> 0.28 | Q12: =IF($P12=0, 0, L12 / $P12) -> 0.7 | R12: =IF($P12=0, 0, M12 / $P12) -> 0.3 | S12: =IF($P12=0, 0, N12 / $P12) -> 0 | T12: =IF($P12=0, 0, O12 / $P12) -> 0 | U12: ='GMV(Total)'!I4 -> 1.3372222 | V12: =C12 * U12 -> 0.37442222 | W12: =Q12 * V12 -> 0.26209556 | X12: =R12 * V12 -> 0.11232667 | Y12: =S12 * V12 -> 0 | Z12: =T12 * V12 -> 0 | AA12: =V12*Parameters!C20 -> 0.13853622 | AB12: =V12*Parameters!D20 -> 0.235886 | AC12: =V12-AUM!O12 -> 0.36839162
B13: L2 | C13: 0.28 | D13: 0.7 | E13: 0.3 | F13: 0 | G13: 0 | H13: 1 | I13: 1 | J13: 0 | K13: 0 | L13: =D13 * C13 * H13 -> 0.196 | M13: =E13 * C13 * I13 -> 0.084 | N13: =F13 * C13 * J13 -> 0 | O13: =G13 * C13 * K13 -> 0 | P13: =L13 + M13 + N13 + O13 -> 0.28 | Q13: =IF($P13=0, 0, L13 / $P13) -> 0.7 | R13: =IF($P13=0, 0, M13 / $P13) -> 0.3 | S13: =IF($P13=0, 0, N13 / $P13) -> 0 | T13: =IF($P13=0, 0, O13 / $P13) -> 0 | U13: ='GMV(Total)'!I4 -> 1.3372222 | V13: =C13 * U13 -> 0.37442222 | W13: =Q13 * V13 -> 0.26209556 | X13: =R13 * V13 -> 0.11232667 | Y13: =S13 * V13 -> 0 | Z13: =T13 * V13 -> 0 | AA13: =V13*Parameters!C21 -> 0.13853622 | AB13: =V13*Parameters!D21 -> 0.235886 | AC13: =V13-AUM!O13 -> 0.36630365
B14: VS | C14: 0.08 | D14: 0.7 | E14: 0.3 | F14: 0 | G14: 0 | H14: 1 | I14: 1 | J14: 0 | K14: 0 | L14: =D14 * C14 * H14 -> 0.056 | M14: =E14 * C14 * I14 -> 0.024 | N14: =F14 * C14 * J14 -> 0 | O14: =G14 * C14 * K14 -> 0 | P14: =L14 + M14 + N14 + O14 -> 0.08 | Q14: =IF($P14=0, 0, L14 / $P14) -> 0.7 | R14: =IF($P14=0, 0, M14 / $P14) -> 0.3 | S14: =IF($P14=0, 0, N14 / $P14) -> 0 | T14: =IF($P14=0, 0, O14 / $P14) -> 0 | U14: ='GMV(Total)'!I4 -> 1.3372222 | V14: =C14 * U14 -> 0.10697778 | W14: =Q14 * V14 -> 0.074884444 | X14: =R14 * V14 -> 0.032093333 | Y14: =S14 * V14 -> 0 | Z14: =T14 * V14 -> 0 | AA14: =V14*Parameters!C22 -> 0.039581778 | AB14: =V14*Parameters!D22 -> 0.067396 | AC14: =V14-AUM!O14 -> 0.10374936
B15: Partner | C15: 0.18 | D15: 0.7 | E15: 0.3 | F15: 0 | G15: 0 | H15: 1 | I15: 0 | J15: 0 | K15: 0 | L15: =D15 * C15 * H15 -> 0.126 | M15: =E15 * C15 * I15 -> 0 | N15: =F15 * C15 * J15 -> 0 | O15: =G15 * C15 * K15 -> 0 | P15: =L15 + M15 + N15 + O15 -> 0.126 | Q15: =IF($P15=0, 0, L15 / $P15) -> 1 | R15: =IF($P15=0, 0, M15 / $P15) -> 0 | S15: =IF($P15=0, 0, N15 / $P15) -> 0 | T15: =IF($P15=0, 0, O15 / $P15) -> 0 | U15: ='GMV(Total)'!I4 -> 1.3372222 | V15: =C15 * U15 -> 0.2407 | W15: =Q15 * V15 -> 0.2407 | X15: =R15 * V15 -> 0 | Y15: =S15 * V15 -> 0 | Z15: =T15 * V15 -> 0 | AA15: =V15*Parameters!C23 -> 0 | AB15: =V15*Parameters!D23 -> 0.2407 | AC15: =V15-AUM!O15 -> 0.2407
B16: L3 | C16: 0.18 | D16: 0.7 | E16: 0.3 | F16: 0 | G16: 0 | H16: 1 | I16: 0 | J16: 0 | K16: 0 | L16: =D16 * C16 * H16 -> 0.126 | M16: =E16 * C16 * I16 -> 0 | N16: =F16 * C16 * J16 -> 0 | O16: =G16 * C16 * K16 -> 0 | P16: =L16 + M16 + N16 + O16 -> 0.126 | Q16: =IF($P16=0, 0, L16 / $P16) -> 1 | R16: =IF($P16=0, 0, M16 / $P16) -> 0 | S16: =IF($P16=0, 0, N16 / $P16) -> 0 | T16: =IF($P16=0, 0, O16 / $P16) -> 0 | U16: ='GMV(Total)'!I4 -> 1.3372222 | V16: =C16 * U16 -> 0.2407 | W16: =Q16 * V16 -> 0.2407 | X16: =R16 * V16 -> 0 | Y16: =S16 * V16 -> 0 | Z16: =T16 * V16 -> 0 | AA16: =V16*Parameters!C24 -> 0 | AB16: =V16*Parameters!D24 -> 0.2407 | AC16: =V16-AUM!O16 -> 0.2407
A17: P3 | B17: L1 | C17: 0.34 | D17: 0.55 | E17: 0.35 | F17: 0.1 | G17: 0 | H17: 1 | I17: 1 | J17: 1 | K17: 0 | L17: =D17 * C17 * H17 -> 0.187 | M17: =E17 * C17 * I17 -> 0.119 | N17: =F17 * C17 * J17 -> 0.034 | O17: =G17 * C17 * K17 -> 0 | P17: =L17 + M17 + N17 + O17 -> 0.34 | Q17: =IF($P17=0, 0, L17 / $P17) -> 0.55 | R17: =IF($P17=0, 0, M17 / $P17) -> 0.35 | S17: =IF($P17=0, 0, N17 / $P17) -> 0.1 | T17: =IF($P17=0, 0, O17 / $P17) -> 0 | U17: ='GMV(Total)'!I5 -> 2.407 | V17: =C17 * U17 -> 0.81838 | W17: =Q17 * V17 -> 0.450109 | X17: =R17 * V17 -> 0.286433 | Y17: =S17 * V17 -> 0.081838 | Z17: =T17 * V17 -> 0 | AA17: =V17*Parameters!C25 -> 0.2823411 | AB17: =V17*Parameters!D25 -> 0.5360389 | AC17: =V17-AUM!O17 -> 0.80565752
B18: L2 | C18: 0.28 | D18: 0.55 | E18: 0.35 | F18: 0.1 | G18: 0 | H18: 1 | I18: 1 | J18: 1 | K18: 0 | L18: =D18 * C18 * H18 -> 0.154 | M18: =E18 * C18 * I18 -> 0.098 | N18: =F18 * C18 * J18 -> 0.028 | O18: =G18 * C18 * K18 -> 0 | P18: =L18 + M18 + N18 + O18 -> 0.28 | Q18: =IF($P18=0, 0, L18 / $P18) -> 0.55 | R18: =IF($P18=0, 0, M18 / $P18) -> 0.35 | S18: =IF($P18=0, 0, N18 / $P18) -> 0.1 | T18: =IF($P18=0, 0, O18 / $P18) -> 0 | U18: ='GMV(Total)'!I5 -> 2.407 | V18: =C18 * U18 -> 0.67396 | W18: =Q18 * V18 -> 0.370678 | X18: =R18 * V18 -> 0.235886 | Y18: =S18 * V18 -> 0.067396 | Z18: =T18 * V18 -> 0 | AA18: =V18*Parameters!C26 -> 0.2325162 | AB18: =V18*Parameters!D26 -> 0.4414438 | AC18: =V18-AUM!O18 -> 0.66004033
B19: VS | C19: 0.1 | D19: 0.55 | E19: 0.35 | F19: 0.1 | G19: 0 | H19: 1 | I19: 1 | J19: 1 | K19: 0 | L19: =D19 * C19 * H19 -> 0.055 | M19: =E19 * C19 * I19 -> 0.035 | N19: =F19 * C19 * J19 -> 0.01 | O19: =G19 * C19 * K19 -> 0 | P19: =L19 + M19 + N19 + O19 -> 0.1 | Q19: =IF($P19=0, 0, L19 / $P19) -> 0.55 | R19: =IF($P19=0, 0, M19 / $P19) -> 0.35 | S19: =IF($P19=0, 0, N19 / $P19) -> 0.1 | T19: =IF($P19=0, 0, O19 / $P19) -> 0 | U19: ='GMV(Total)'!I5 -> 2.407 | V19: =C19 * U19 -> 0.2407 | W19: =Q19 * V19 -> 0.132385 | X19: =R19 * V19 -> 0.084245 | Y19: =S19 * V19 -> 0.02407 | Z19: =T19 * V19 -> 0 | AA19: =V19*Parameters!C27 -> 0.0830415 | AB19: =V19*Parameters!D27 -> 0.1576585 | AC19: =V19-AUM!O19 -> 0.23392778
B20: Partner | C20: 0.14 | D20: 0.55 | E20: 0.35 | F20: 0.1 | G20: 0 | H20: 1 | I20: 0 | J20: 0 | K20: 0 | L20: =D20 * C20 * H20 -> 0.077 | M20: =E20 * C20 * I20 -> 0 | N20: =F20 * C20 * J20 -> 0 | O20: =G20 * C20 * K20 -> 0 | P20: =L20 + M20 + N20 + O20 -> 0.077 | Q20: =IF($P20=0, 0, L20 / $P20) -> 1 | R20: =IF($P20=0, 0, M20 / $P20) -> 0 | S20: =IF($P20=0, 0, N20 / $P20) -> 0 | T20: =IF($P20=0, 0, O20 / $P20) -> 0 | U20: ='GMV(Total)'!I5 -> 2.407 | V20: =C20 * U20 -> 0.33698 | W20: =Q20 * V20 -> 0.33698 | X20: =R20 * V20 -> 0 | Y20: =S20 * V20 -> 0 | Z20: =T20 * V20 -> 0 | AA20: =V20*Parameters!C28 -> 0 | AB20: =V20*Parameters!D28 -> 0.33698 | AC20: =V20-AUM!O20 -> 0.33698
B21: L3 | C21: 0.14 | D21: 0.55 | E21: 0.35 | F21: 0.1 | G21: 0 | H21: 1 | I21: 0 | J21: 0 | K21: 0 | L21: =D21 * C21 * H21 -> 0.077 | M21: =E21 * C21 * I21 -> 0 | N21: =F21 * C21 * J21 -> 0 | O21: =G21 * C21 * K21 -> 0 | P21: =L21 + M21 + N21 + O21 -> 0.077 | Q21: =IF($P21=0, 0, L21 / $P21) -> 1 | R21: =IF($P21=0, 0, M21 / $P21) -> 0 | S21: =IF($P21=0, 0, N21 / $P21) -> 0 | T21: =IF($P21=0, 0, O21 / $P21) -> 0 | U21: ='GMV(Total)'!I5 -> 2.407 | V21: =C21 * U21 -> 0.33698 | W21: =Q21 * V21 -> 0.33698 | X21: =R21 * V21 -> 0 | Y21: =S21 * V21 -> 0 | Z21: =T21 * V21 -> 0 | AA21: =V21*Parameters!C29 -> 0 | AB21: =V21*Parameters!D29 -> 0.33698 | AC21: =V21-AUM!O21 -> 0.33698
A22: P4 | B22: L1 | C22: 0.4 | D22: 0.4 | E22: 0.4 | F22: 0.2 | G22: 0 | H22: 1 | I22: 1 | J22: 1 | K22: 0 | L22: =D22 * C22 * H22 -> 0.16 | M22: =E22 * C22 * I22 -> 0.16 | N22: =F22 * C22 * J22 -> 0.08 | O22: =G22 * C22 * K22 -> 0 | P22: =L22 + M22 + N22 + O22 -> 0.4 | Q22: =IF($P22=0, 0, L22 / $P22) -> 0.4 | R22: =IF($P22=0, 0, M22 / $P22) -> 0.4 | S22: =IF($P22=0, 0, N22 / $P22) -> 0.2 | T22: =IF($P22=0, 0, O22 / $P22) -> 0 | U22: ='GMV(Total)'!I6 -> 3.6105 | V22: =C22 * U22 -> 1.4442 | W22: =Q22 * V22 -> 0.57768 | X22: =R22 * V22 -> 0.57768 | Y22: =S22 * V22 -> 0.28884 | Z22: =T22 * V22 -> 0 | AA22: =V22*Parameters!C30 -> 0.462144 | AB22: =V22*Parameters!D30 -> 0.982056 | AC22: =V22-AUM!O22 -> 1.4227287
B23: L2 | C23: 0.28 | D23: 0.4 | E23: 0.4 | F23: 0.2 | G23: 0 | H23: 1 | I23: 1 | J23: 1 | K23: 0 | L23: =D23 * C23 * H23 -> 0.112 | M23: =E23 * C23 * I23 -> 0.112 | N23: =F23 * C23 * J23 -> 0.056 | O23: =G23 * C23 * K23 -> 0 | P23: =L23 + M23 + N23 + O23 -> 0.28 | Q23: =IF($P23=0, 0, L23 / $P23) -> 0.4 | R23: =IF($P23=0, 0, M23 / $P23) -> 0.4 | S23: =IF($P23=0, 0, N23 / $P23) -> 0.2 | T23: =IF($P23=0, 0, O23 / $P23) -> 0 | U23: ='GMV(Total)'!I6 -> 3.6105 | V23: =C23 * U23 -> 1.01094 | W23: =Q23 * V23 -> 0.404376 | X23: =R23 * V23 -> 0.404376 | Y23: =S23 * V23 -> 0.202188 | Z23: =T23 * V23 -> 0 | AA23: =V23*Parameters!C31 -> 0.3235008 | AB23: =V23*Parameters!D31 -> 0.6874392 | AC23: =V23-AUM!O23 -> 0.99120905
B24: VS | C24: 0.12 | D24: 0.4 | E24: 0.4 | F24: 0.2 | G24: 0 | H24: 1 | I24: 1 | J24: 1 | K24: 0 | L24: =D24 * C24 * H24 -> 0.048 | M24: =E24 * C24 * I24 -> 0.048 | N24: =F24 * C24 * J24 -> 0.024 | O24: =G24 * C24 * K24 -> 0 | P24: =L24 + M24 + N24 + O24 -> 0.12 | Q24: =IF($P24=0, 0, L24 / $P24) -> 0.4 | R24: =IF($P24=0, 0, M24 / $P24) -> 0.4 | S24: =IF($P24=0, 0, N24 / $P24) -> 0.2 | T24: =IF($P24=0, 0, O24 / $P24) -> 0 | U24: ='GMV(Total)'!I6 -> 3.6105 | V24: =C24 * U24 -> 0.43326 | W24: =Q24 * V24 -> 0.173304 | X24: =R24 * V24 -> 0.173304 | Y24: =S24 * V24 -> 0.086652 | Z24: =T24 * V24 -> 0 | AA24: =V24*Parameters!C32 -> 0.1386432 | AB24: =V24*Parameters!D32 -> 0.2946168 | AC24: =V24-AUM!O24 -> 0.42195486
B25: Partner | C25: 0.1 | D25: 0.4 | E25: 0.4 | F25: 0.2 | G25: 0 | H25: 1 | I25: 0 | J25: 0 | K25: 0 | L25: =D25 * C25 * H25 -> 0.04 | M25: =E25 * C25 * I25 -> 0 | N25: =F25 * C25 * J25 -> 0 | O25: =G25 * C25 * K25 -> 0 | P25: =L25 + M25 + N25 + O25 -> 0.04 | Q25: =IF($P25=0, 0, L25 / $P25) -> 1 | R25: =IF($P25=0, 0, M25 / $P25) -> 0 | S25: =IF($P25=0, 0, N25 / $P25) -> 0 | T25: =IF($P25=0, 0, O25 / $P25) -> 0 | U25: ='GMV(Total)'!I6 -> 3.6105 | V25: =C25 * U25 -> 0.36105 | W25: =Q25 * V25 -> 0.36105 | X25: =R25 * V25 -> 0 | Y25: =S25 * V25 -> 0 | Z25: =T25 * V25 -> 0 | AA25: =V25*Parameters!C33 -> 0 | AB25: =V25*Parameters!D33 -> 0.36105 | AC25: =V25-AUM!O25 -> 0.36105
B26: L3 | C26: 0.1 | D26: 0.4 | E26: 0.4 | F26: 0.2 | G26: 0 | H26: 1 | I26: 0 | J26: 0 | K26: 0 | L26: =D26 * C26 * H26 -> 0.04 | M26: =E26 * C26 * I26 -> 0 | N26: =F26 * C26 * J26 -> 0 | O26: =G26 * C26 * K26 -> 0 | P26: =L26 + M26 + N26 + O26 -> 0.04 | Q26: =IF($P26=0, 0, L26 / $P26) -> 1 | R26: =IF($P26=0, 0, M26 / $P26) -> 0 | S26: =IF($P26=0, 0, N26 / $P26) -> 0 | T26: =IF($P26=0, 0, O26 / $P26) -> 0 | U26: ='GMV(Total)'!I6 -> 3.6105 | V26: =C26 * U26 -> 0.36105 | W26: =Q26 * V26 -> 0.36105 | X26: =R26 * V26 -> 0 | Y26: =S26 * V26 -> 0 | Z26: =T26 * V26 -> 0 | AA26: =V26*Parameters!C34 -> 0 | AB26: =V26*Parameters!D34 -> 0.36105 | AC26: =V26-AUM!O26 -> 0.36105
A27: P5 | B27: L1 | C27: 0.45 | D27: 0.3 | E27: 0.35 | F27: 0.2 | G27: 0.15 | H27: 1 | I27: 1 | J27: 1 | K27: 1 | L27: =D27 * C27 * H27 -> 0.135 | M27: =E27 * C27 * I27 -> 0.1575 | N27: =F27 * C27 * J27 -> 0.09 | O27: =G27 * C27 * K27 -> 0.0675 | P27: =L27 + M27 + N27 + O27 -> 0.45 | Q27: =IF($P27=0, 0, L27 / $P27) -> 0.3 | R27: =IF($P27=0, 0, M27 / $P27) -> 0.35 | S27: =IF($P27=0, 0, N27 / $P27) -> 0.2 | T27: =IF($P27=0, 0, O27 / $P27) -> 0.15 | U27: ='GMV(Total)'!I7 -> 4.3326 | V27: =C27 * U27 -> 1.94967 | W27: =Q27 * V27 -> 0.584901 | X27: =R27 * V27 -> 0.6823845 | Y27: =S27 * V27 -> 0.389934 | Z27: =T27 * V27 -> 0.2924505 | AA27: =V27*Parameters!C35 -> 0.51666255 | AB27: =V27*Parameters!D35 -> 1.4330075 | AC27: =V27-AUM!O27 -> 1.9253075
B28: L2 | C28: 0.28 | D28: 0.3 | E28: 0.35 | F28: 0.2 | G28: 0.15 | H28: 1 | I28: 1 | J28: 1 | K28: 0 | L28: =D28 * C28 * H28 -> 0.084 | M28: =E28 * C28 * I28 -> 0.098 | N28: =F28 * C28 * J28 -> 0.056 | O28: =G28 * C28 * K28 -> 0 | P28: =L28 + M28 + N28 + O28 -> 0.238 | Q28: =IF($P28=0, 0, L28 / $P28) -> 0.35294118 | R28: =IF($P28=0, 0, M28 / $P28) -> 0.41176471 | S28: =IF($P28=0, 0, N28 / $P28) -> 0.23529412 | T28: =IF($P28=0, 0, O28 / $P28) -> 0 | U28: ='GMV(Total)'!I7 -> 4.3326 | V28: =C28 * U28 -> 1.213128 | W28: =Q28 * V28 -> 0.42816282 | X28: =R28 * V28 -> 0.49952329 | Y28: =S28 * V28 -> 0.28544188 | Z28: =T28 * V28 -> 0 | AA28: =V28*Parameters!C36 -> 0.37821049 | AB28: =V28*Parameters!D36 -> 0.83491751 | AC28: =V28-AUM!O28 -> 1.1899239
B29: VS | C29: 0.12 | D29: 0.3 | E29: 0.35 | F29: 0.2 | G29: 0.15 | H29: 1 | I29: 1 | J29: 1 | K29: 0 | L29: =D29 * C29 * H29 -> 0.036 | M29: =E29 * C29 * I29 -> 0.042 | N29: =F29 * C29 * J29 -> 0.024 | O29: =G29 * C29 * K29 -> 0 | P29: =L29 + M29 + N29 + O29 -> 0.102 | Q29: =IF($P29=0, 0, L29 / $P29) -> 0.35294118 | R29: =IF($P29=0, 0, M29 / $P29) -> 0.41176471 | S29: =IF($P29=0, 0, N29 / $P29) -> 0.23529412 | T29: =IF($P29=0, 0, O29 / $P29) -> 0 | U29: ='GMV(Total)'!I7 -> 4.3326 | V29: =C29 * U29 -> 0.519912 | W29: =Q29 * V29 -> 0.18349835 | X29: =R29 * V29 -> 0.21408141 | Y29: =S29 * V29 -> 0.12233224 | Z29: =T29 * V29 -> 0 | AA29: =V29*Parameters!C37 -> 0.16209021 | AB29: =V29*Parameters!D37 -> 0.35782179 | AC29: =V29-AUM!O29 -> 0.50669497
B30: Partner | C30: 0.08 | D30: 0.3 | E30: 0.35 | F30: 0.2 | G30: 0.15 | H30: 1 | I30: 0 | J30: 0 | K30: 0 | L30: =D30 * C30 * H30 -> 0.024 | M30: =E30 * C30 * I30 -> 0 | N30: =F30 * C30 * J30 -> 0 | O30: =G30 * C30 * K30 -> 0 | P30: =L30 + M30 + N30 + O30 -> 0.024 | Q30: =IF($P30=0, 0, L30 / $P30) -> 1 | R30: =IF($P30=0, 0, M30 / $P30) -> 0 | S30: =IF($P30=0, 0, N30 / $P30) -> 0 | T30: =IF($P30=0, 0, O30 / $P30) -> 0 | U30: ='GMV(Total)'!I7 -> 4.3326 | V30: =C30 * U30 -> 0.346608 | W30: =Q30 * V30 -> 0.346608 | X30: =R30 * V30 -> 0 | Y30: =S30 * V30 -> 0 | Z30: =T30 * V30 -> 0 | AA30: =V30*Parameters!C38 -> 0 | AB30: =V30*Parameters!D38 -> 0.346608 | AC30: =V30-AUM!O30 -> 0.346608
B31: L3 | C31: 0.07 | D31: 0.3 | E31: 0.35 | F31: 0.2 | G31: 0.15 | H31: 1 | I31: 0 | J31: 0 | K31: 0 | L31: =D31 * C31 * H31 -> 0.021 | M31: =E31 * C31 * I31 -> 0 | N31: =F31 * C31 * J31 -> 0 | O31: =G31 * C31 * K31 -> 0 | P31: =L31 + M31 + N31 + O31 -> 0.021 | Q31: =IF($P31=0, 0, L31 / $P31) -> 1 | R31: =IF($P31=0, 0, M31 / $P31) -> 0 | S31: =IF($P31=0, 0, N31 / $P31) -> 0 | T31: =IF($P31=0, 0, O31 / $P31) -> 0 | U31: ='GMV(Total)'!I7 -> 4.3326 | V31: =C31 * U31 -> 0.303282 | W31: =Q31 * V31 -> 0.303282 | X31: =R31 * V31 -> 0 | Y31: =S31 * V31 -> 0 | Z31: =T31 * V31 -> 0 | AA31: =V31*Parameters!C39 -> 0 | AB31: =V31*Parameters!D39 -> 0.303282 | AC31: =V31-AUM!O31 -> 0.303282

Sheet AUM
A1: Phase | B1: Layer | C1: R | D1: r | E1: p | F1: d | G1: vᵖʳⁱᵐ (B) | H1: vˢᵉᶜ (B) | I1: AUMₖ,ₗ (B) | J1: Scale sₖ | K1: AUMₖ,ₗ(M) | L1: vᵖʳⁱᵐ (M) | M1: vˢᵉᶜ (M) | N1: x_rebalancing(B) | O1: x_month (B)
A2: P0 | B2: L1 | C2: 12 | D2: =Parameters!F10 -> 0.03 | E2: =C2*D2/(C2*D2+Parameters!E10) -> 0.50704225 | F2: - | G2: ='GMV(Layer)'!AA2 -> 0.0040521886 | H2: ='GMV(Layer)'!AB2 -> 0.0060782828 | I2: =G2/(C2*D2+Parameters!E10) -> 0.0057073078 | J2: 0 | K2: =I2*1000 -> 5.7073078 | L2: =G2*1000 -> 4.0521886 | M2: =H2*1000 -> 6.0782828 | N2: =C2*D2*I2 -> 0.0020546308 | O2: =N2/12 -> 0.00017121923
B3: L2 | C3: 26 | D3: =Parameters!F11 -> 0.03 | E3: =C3*D3/(C3*D3+Parameters!E11) -> 0.69026549 | F3: - | G3: ='GMV(Layer)'!AA3 -> 0.0081043771 | H3: ='GMV(Layer)'!AB3 -> 0.012156566 | I3: =G3/(C3*D3+Parameters!E11) -> 0.0071720151 | J3: 0 | K3: =I3*1000 -> 7.1720151 | L3: =G3*1000 -> 8.1043771 | M3: =H3*1000 -> 12.156566 | N3: =C3*D3*I3 -> 0.0055941718 | O3: =N3/12 -> 0.00046618098
B4: VS | C4: 26 | D4: =Parameters!F12 -> 0.7 | E4: =C4*D4/(C4*D4+Parameters!E12) -> 0.98113208 | F4: - | G4: ='GMV(Layer)'!AA4 -> 0 | H4: ='GMV(Layer)'!AB4 -> 0 | I4: =G4/(C4*D4+Parameters!E12) -> 0 | J4: 0 | K4: =I4*1000 -> 0 | L4: =G4*1000 -> 0 | M4: =H4*1000 -> 0 | N4: =C4*D4*I4 -> 0 | O4: =N4/12 -> 0
B5: Partner | C5: - | D5: =Parameters!F13 -> - | E5: - | F5: 2 | G5: ='GMV(Layer)'!AA5 -> 0 | H5: ='GMV(Layer)'!AB5 -> 0.0709133 | I5: =H5*(F5/365) -> 0.00038856603 | J5: 0 | K5: =I5*1000 -> 0.38856603 | L5: =G5*1000 -> 0 | M5: =H5*1000 -> 70.9133 | N5: 0 | O5: =N5/12 -> 0
B6: L3 | C6: - | D6: =Parameters!F14 -> - | E6: - | F6: 2 | G6: ='GMV(Layer)'!AA6 -> 0 | H6: ='GMV(Layer)'!AB6 -> 0.10130471 | I6: =H6*(F6/365) -> 0.00055509432 | J6: 0 | K6: =I6*1000 -> 0.55509432 | L6: =G6*1000 -> 0 | M6: =H6*1000 -> 101.30471 | N6: 0 | O6: =N6/12 -> 0
A7: P1 | B7: L1 | C7: 12 | D7: =Parameters!F15 -> 0.03 | E7: =C7*D7/(C7*D7+Parameters!E15) -> 0.50704225 | F7: - | G7: ='GMV(Layer)'!AA7 -> 0.032417508 | H7: ='GMV(Layer)'!AB7 -> 0.048626263 | I7: =G7/(C7*D7+Parameters!E15) -> 0.045658463 | J7: ='GMV(Total)'!J3/'GMV(Total)'!J7 -> 0.072446378 | K7: =I7*1000 -> 45.658463 | L7: =G7*1000 -> 32.417508 | M7: =H7*1000 -> 48.626263 | N7: =C7*D7*I7 -> 0.016437047 | O7: =N7/12 -> 0.0013697539
B8: L2 | C8: 26 | D8: =Parameters!F16 -> 0.03 | E8: =C8*D8/(C8*D8+Parameters!E16) -> 0.69026549 | F8: - | G8: ='GMV(Layer)'!AA8 -> 0.040521886 | H8: ='GMV(Layer)'!AB8 -> 0.060782828 | I8: =G8/(C8*D8+Parameters!E16) -> 0.035860076 | J8: ='GMV(Total)'!J3/'GMV(Total)'!J7 -> 0.072446378 | K8: =I8*1000 -> 35.860076 | L8: =G8*1000 -> 40.521886 | M8: =H8*1000 -> 60.782828 | N8: =C8*D8*I8 -> 0.027970859 | O8: =N8/12 -> 0.0023309049
B9: VS | C9: 26 | D9: =Parameters!F17 -> 0.7 | E9: =C9*D9/(C9*D9+Parameters!E17) -> 0.98113208 | F9: - | G9: ='GMV(Layer)'!AA9 -> 0.0081043771 | H9: ='GMV(Layer)'!AB9 -> 0.012156566 | I9: =G9/(C9*D9+Parameters!E17) -> 0.00043689364 | J9: ='GMV(Total)'!J3/'GMV(Total)'!J7 -> 0.072446378 | K9: =I9*1000 -> 0.43689364 | L9: =G9*1000 -> 8.1043771 | M9: =H9*1000 -> 12.156566 | N9: =C9*D9*I9 -> 0.0079514643 | O9: =N9/12 -> 0.00066262203
B10: Partner | C10: - | D10: =Parameters!F18 -> - | E10: - | F10: 2 | G10: ='GMV(Layer)'!AA10 -> 0 | H10: ='GMV(Layer)'!AB10 -> 0.10130471 | I10: =H10*(F10/365) -> 0.00055509432 | J10: ='GMV(Total)'!J3/'GMV(Total)'!J7 -> 0.072446378 | K10: =I10*1000 -> 0.55509432 | L10: =G10*1000 -> 0 | M10: =H10*1000 -> 101.30471 | N10: 0 | O10: =N10/12 -> 0
B11: L3 | C11: 0 | D11: =Parameters!F19 -> - | E11: - | F11: 2 | G11: ='GMV(Layer)'!AA11 -> 0 | H11: ='GMV(Layer)'!AB11 -> 0.10130471 | I11: =H11*(F11/365) -> 0.00055509432 | J11: ='GMV(Total)'!J3/'GMV(Total)'!J7 -> 0.072446378 | K11: =I11*1000 -> 0.55509432 | L11: =G11*1000 -> 0 | M11: =H11*1000 -> 101.30471 | N11: 0 | O11: =N11/12 -> 0
A12: P2 | B12: L1 | C12: 12 | D12: =Parameters!F20 -> 0.036 | E12: =C12*D12/(C12*D12+Parameters!E20) -> 0.52237001 | F12: - | G12: ='GMV(Layer)'!AA12 -> 0.13853622 | H12: ='GMV(Layer)'!AB12 -> 0.235886 | I12: =G12/(C12*D12+Parameters!E20) -> 0.16751659 | J12: ='GMV(Total)'!J4/'GMV(Total)'!J7 -> 0.18611811 | K12: =I12*1000 -> 167.51659 | L12: =G12*1000 -> 138.53622 | M12: =H12*1000 -> 235.886 | N12: =C12*D12*I12 -> 0.072367168 | O12: =N12/12 -> 0.0060305973
B13: L2 | C13: 26 | D13: =Parameters!F21 -> 0.036 | E13: =C13*D13/(C13*D13+Parameters!E21) -> 0.70323065 | F13: - | G13: ='GMV(Layer)'!AA13 -> 0.13853622 | H13: ='GMV(Layer)'!AB13 -> 0.235886 | I13: =G13/(C13*D13+Parameters!E21) -> 0.10408431 | J13: ='GMV(Total)'!J4/'GMV(Total)'!J7 -> 0.18611811 | K13: =I13*1000 -> 104.08431 | L13: =G13*1000 -> 138.53622 | M13: =H13*1000 -> 235.886 | N13: =C13*D13*I13 -> 0.097422918 | O13: =N13/12 -> 0.0081185765
B14: VS | C14: 26 | D14: =Parameters!F22 -> 0.7 | E14: =C14*D14/(C14*D14+Parameters!E22) -> 0.97875773 | F14: - | G14: ='GMV(Layer)'!AA14 -> 0.039581778 | H14: ='GMV(Layer)'!AB14 -> 0.067396 | I14: =G14/(C14*D14+Parameters!E22) -> 0.0021286248 | J14: ='GMV(Total)'!J4/'GMV(Total)'!J7 -> 0.18611811 | K14: =I14*1000 -> 2.1286248 | L14: =G14*1000 -> 39.581778 | M14: =H14*1000 -> 67.396 | N14: =C14*D14*I14 -> 0.038740971 | O14: =N14/12 -> 0.0032284142
B15: Partner | C15: - | D15: =Parameters!F23 -> - | E15: - | F15: 2 | G15: ='GMV(Layer)'!AA15 -> 0 | H15: ='GMV(Layer)'!AB15 -> 0.2407 | I15: =H15*(F15/365) -> 0.0013189041 | J15: ='GMV(Total)'!J4/'GMV(Total)'!J7 -> 0.18611811 | K15: =I15*1000 -> 1.3189041 | L15: =G15*1000 -> 0 | M15: =H15*1000 -> 240.7 | N15: 0 | O15: =N15/12 -> 0
B16: L3 | C16: - | D16: =Parameters!F24 -> - | E16: - | F16: 2 | G16: ='GMV(Layer)'!AA16 -> 0 | H16: ='GMV(Layer)'!AB16 -> 0.2407 | I16: =H16*(F16/365) -> 0.0013189041 | J16: ='GMV(Total)'!J4/'GMV(Total)'!J7 -> 0.18611811 | K16: =I16*1000 -> 1.3189041 | L16: =G16*1000 -> 0 | M16: =H16*1000 -> 240.7 | N16: 0 | O16: =N16/12 -> 0
A17: P3 | B17: L1 | C17: 12 | D17: =Parameters!F25 -> 0.039 | E17: =C17*D17/(C17*D17+Parameters!E25) -> 0.5407279 | F17: - | G17: ='GMV(Layer)'!AA17 -> 0.2823411 | H17: ='GMV(Layer)'!AB17 -> 0.5360389 | I17: =G17/(C17*D17+Parameters!E25) -> 0.32621733 | J17: ='GMV(Total)'!J5/'GMV(Total)'!J7 -> 0.45360921 | K17: =I17*1000 -> 326.21733 | L17: =G17*1000 -> 282.3411 | M17: =H17*1000 -> 536.0389 | N17: =C17*D17*I17 -> 0.15266971 | O17: =N17/12 -> 0.012722476
B18: L2 | C18: 26 | D18: =Parameters!F26 -> 0.039 | E18: =C18*D18/(C18*D18+Parameters!E26) -> 0.7183847 | F18: - | G18: ='GMV(Layer)'!AA18 -> 0.2325162 | H18: ='GMV(Layer)'!AB18 -> 0.4414438 | I18: =G18/(C18*D18+Parameters!E26) -> 0.16472986 | J18: ='GMV(Total)'!J5/'GMV(Total)'!J7 -> 0.45360921 | K18: =I18*1000 -> 164.72986 | L18: =G18*1000 -> 232.5162 | M18: =H18*1000 -> 441.4438 | N18: =C18*D18*I18 -> 0.16703608 | O18: =N18/12 -> 0.013919673
B19: VS | C19: 26 | D19: =Parameters!F27 -> 0.7 | E19: =C19*D19/(C19*D19+Parameters!E27) -> 0.97862616 | F19: - | G19: ='GMV(Layer)'!AA19 -> 0.0830415 | H19: ='GMV(Layer)'!AB19 -> 0.1576585 | I19: =G19/(C19*D19+Parameters!E27) -> 0.0044651969 | J19: ='GMV(Total)'!J5/'GMV(Total)'!J7 -> 0.45360921 | K19: =I19*1000 -> 4.4651969 | L19: =G19*1000 -> 83.0415 | M19: =H19*1000 -> 157.6585 | N19: =C19*D19*I19 -> 0.081266584 | O19: =N19/12 -> 0.0067722154
B20: Partner | C20: - | D20: =Parameters!F28 -> - | E20: - | F20: 2 | G20: ='GMV(Layer)'!AA20 -> 0 | H20: ='GMV(Layer)'!AB20 -> 0.33698 | I20: =H20*(F20/365) -> 0.0018464658 | J20: ='GMV(Total)'!J5/'GMV(Total)'!J7 -> 0.45360921 | K20: =I20*1000 -> 1.8464658 | L20: =G20*1000 -> 0 | M20: =H20*1000 -> 336.98 | N20: 0 | O20: =N20/12 -> 0
B21: L3 | C21: - | D21: =Parameters!F29 -> - | E21: - | F21: 2 | G21: ='GMV(Layer)'!AA21 -> 0 | H21: ='GMV(Layer)'!AB21 -> 0.33698 | I21: =H21*(F21/365) -> 0.0018464658 | J21: ='GMV(Total)'!J5/'GMV(Total)'!J7 -> 0.45360921 | K21: =I21*1000 -> 1.8464658 | L21: =G21*1000 -> 0 | M21: =H21*1000 -> 336.98 | N21: 0 | O21: =N21/12 -> 0
A22: P4 | B22: L1 | C22: 12 | D22: =Parameters!F30 -> 0.042 | E22: =C22*D22/(C22*D22+Parameters!E30) -> 0.55752212 | F22: - | G22: ='GMV(Layer)'!AA22 -> 0.462144 | H22: ='GMV(Layer)'!AB22 -> 0.982056 | I22: =G22/(C22*D22+Parameters!E30) -> 0.51122124 | J22: ='GMV(Total)'!J6/'GMV(Total)'!J7 -> 0.74535599 | K22: =I22*1000 -> 511.22124 | L22: =G22*1000 -> 462.144 | M22: =H22*1000 -> 982.056 | N22: =C22*D22*I22 -> 0.2576555 | O22: =N22/12 -> 0.021471292
B23: L2 | C23: 26 | D23: =Parameters!F31 -> 0.042 | E23: =C23*D23/(C23*D23+Parameters!E31) -> 0.73190349 | F23: - | G23: ='GMV(Layer)'!AA23 -> 0.3235008 | H23: ='GMV(Layer)'!AB23 -> 0.6874392 | I23: =G23/(C23*D23+Parameters!E31) -> 0.21682359 | J23: ='GMV(Total)'!J6/'GMV(Total)'!J7 -> 0.74535599 | K23: =I23*1000 -> 216.82359 | L23: =G23*1000 -> 323.5008 | M23: =H23*1000 -> 687.4392 | N23: =C23*D23*I23 -> 0.23677136 | O23: =N23/12 -> 0.019730947
B24: VS | C24: 26 | D24: =Parameters!F32 -> 0.7 | E24: =C24*D24/(C24*D24+Parameters!E32) -> 0.97849462 | F24: - | G24: ='GMV(Layer)'!AA24 -> 0.1386432 | H24: ='GMV(Layer)'!AB24 -> 0.2946168 | I24: =G24/(C24*D24+Parameters!E32) -> 0.0074539355 | J24: ='GMV(Total)'!J6/'GMV(Total)'!J7 -> 0.74535599 | K24: =I24*1000 -> 7.4539355 | L24: =G24*1000 -> 138.6432 | M24: =H24*1000 -> 294.6168 | N24: =C24*D24*I24 -> 0.13566163 | O24: =N24/12 -> 0.011305135
B25: Partner | C25: - | D25: =Parameters!F33 -> - | E25: - | F25: 2 | G25: ='GMV(Layer)'!AA25 -> 0 | H25: ='GMV(Layer)'!AB25 -> 0.36105 | I25: =H25*(F25/365) -> 0.0019783562 | J25: ='GMV(Total)'!J6/'GMV(Total)'!J7 -> 0.74535599 | K25: =I25*1000 -> 1.9783562 | L25: =G25*1000 -> 0 | M25: =H25*1000 -> 361.05 | N25: 0 | O25: =N25/12 -> 0
B26: L3 | C26: - | D26: =Parameters!F34 -> - | E26: - | F26: 2 | G26: ='GMV(Layer)'!AA26 -> 0 | H26: ='GMV(Layer)'!AB26 -> 0.36105 | I26: =H26*(F26/365) -> 0.0019783562 | J26: ='GMV(Total)'!J6/'GMV(Total)'!J7 -> 0.74535599 | K26: =I26*1000 -> 1.9783562 | L26: =G26*1000 -> 0 | M26: =H26*1000 -> 361.05 | N26: 0 | O26: =N26/12 -> 0
A27: P5 | B27: L1 | C27: 12 | D27: =Parameters!F35 -> 0.041 | E27: =C27*D27/(C27*D27+Parameters!E35) -> 0.56584244 | F27: - | G27: ='GMV(Layer)'!AA27 -> 0.51666255 | H27: ='GMV(Layer)'!AB27 -> 1.4330075 | I27: =G27/(C27*D27+Parameters!E35) -> 0.5942065 | J27: 1 | K27: =I27*1000 -> 594.2065 | L27: =G27*1000 -> 516.66255 | M27: =H27*1000 -> 1433.0075 | N27: =C27*D27*I27 -> 0.2923496 | O27: =N27/12 -> 0.024362466
B28: L2 | C28: 26 | D28: =Parameters!F36 -> 0.042941176 | E28: =C28*D28/(C28*D28+Parameters!E36) -> 0.73622964 | F28: - | G28: ='GMV(Layer)'!AA28 -> 0.37821049 | H28: ='GMV(Layer)'!AB28 -> 0.83491751 | I28: =G28/(C28*D28+Parameters!E36) -> 0.2494018 | J28: 1 | K28: =I28*1000 -> 249.4018 | L28: =G28*1000 -> 378.21049 | M28: =H28*1000 -> 834.91751 | N28: =C28*D28*I28 -> 0.27844977 | O28: =N28/12 -> 0.023204148
B29: VS | C29: 26 | D29: =Parameters!F37 -> 0.7 | E29: =C29*D29/(C29*D29+Parameters!E37) -> 0.97849462 | F29: - | G29: ='GMV(Layer)'!AA29 -> 0.16209021 | H29: ='GMV(Layer)'!AB29 -> 0.35782179 | I29: =G29/(C29*D29+Parameters!E37) -> 0.0087145275 | J29: 1 | K29: =I29*1000 -> 8.7145275 | L29: =G29*1000 -> 162.09021 | M29: =H29*1000 -> 357.82179 | N29: =C29*D29*I29 -> 0.1586044 | O29: =N29/12 -> 0.013217033
B30: Partner | C30: - | D30: =Parameters!F38 -> - | E30: - | F30: 1 | G30: ='GMV(Layer)'!AA30 -> 0 | H30: ='GMV(Layer)'!AB30 -> 0.346608 | I30: =H30*(F30/365) -> 0.00094961096 | J30: 1 | K30: =I30*1000 -> 0.94961096 | L30: =G30*1000 -> 0 | M30: =H30*1000 -> 346.608 | N30: 0 | O30: =N30/12 -> 0
B31: L3 | C31: - | D31: =Parameters!F39 -> - | E31: - | F31: 2 | G31: ='GMV(Layer)'!AA31 -> 0 | H31: ='GMV(Layer)'!AB31 -> 0.303282 | I31: =H31*(F31/365) -> 0.0016618192 | J31: 1 | K31: =I31*1000 -> 1.6618192 | L31: =G31*1000 -> 0 | M31: =H31*1000 -> 303.282 | N31: 0 | O31: =N31/12 -> 0
K33: =SUM(K27:K31) -> 854.93426

Sheet Launch Fee
A1: Phase | B1: Base Fee(Hype) | C1: δ (Discount Rate) | D1: wₙ (Native Usage) | E1: Multiplier (1 − wₙ · δ) | F1: Effective Fee (HYPE eqv.) | G1: F_L3 | H1: Launch Count / mo | I1: Graduation Ratio (θ) | J1: Graduation Count / mo | K1: Monthly Fee (HYPE) | L1: Annual Fee (HYPE) | M1: Monthly Fee (USD) | N1: Annual Fee (USD) | O1: Monthly Fee (B)
A2: P0 | B2: 0 | C2: =Parameters!K10 -> 0.2 | D2: =Parameters!J10 -> 0 | E2: =Parameters!L10 -> 1 | F2: =표3[[#This Row],[Base Fee(Hype)]]*표3[[#This Row],[Multiplier (1 − wₙ · δ)]] -> 0 | G2: ='GMV(Layer)'!V6/'GMV(Layer)'!V11 -> 1 | H2: =H3*표3[[#This Row],[F_L3]] -> 57575.758 | I2: 0 | J2: =표3[[#This Row],[Launch Count / mo]]*표3[[#This Row],[Graduation Ratio (θ)]] -> 0 | K2: =표3[[#This Row],[Effective Fee (HYPE eqv.)]]*표3[[#This Row],[Graduation Count / mo]] -> 0 | L2: =표3[[#This Row],[Monthly Fee (HYPE)]]*12 -> 0 | M2: {=표3[[#This Row],[Monthly Fee (HYPE)]]*표5[$HYPE in USD]} -> 0 | N2: =표3[[#This Row],[Monthly Fee (USD)]]*12 -> 0 | O2: =표3[[#This Row],[Monthly Fee (USD)]]/1000000000 -> 0
A3: P1 | B3: 0.045 | C3: =Parameters!K11 -> 0.2 | D3: =Parameters!J11 -> 0.15 | E3: =Parameters!L11 -> 0.97 | F3: =표3[[#This Row],[Base Fee(Hype)]]*표3[[#This Row],[Multiplier (1 − wₙ · δ)]] -> 0.04365 | G3: ='GMV(Layer)'!V11/'GMV(Layer)'!V16 -> 0.42087542 | H3: =H4*표3[[#This Row],[F_L3]] -> 57575.758 | I3: 0.005 | J3: =표3[[#This Row],[Launch Count / mo]]*표3[[#This Row],[Graduation Ratio (θ)]] -> 287.87879 | K3: =표3[[#This Row],[Effective Fee (HYPE eqv.)]]*표3[[#This Row],[Graduation Count / mo]] -> 12.565909 | L3: =표3[[#This Row],[Monthly Fee (HYPE)]]*12 -> 150.79091 | M3: {=표3[[#This Row],[Monthly Fee (HYPE)]]*표5[$HYPE in USD]} -> 502.63636 | N3: =표3[[#This Row],[Monthly Fee (USD)]]*12 -> 6031.6364 | O3: =표3[[#This Row],[Monthly Fee (USD)]]/1000000000 -> 5.0263636e-07
A4: P2 | B4: 0.045 | C4: =Parameters!K12 -> 0.2 | D4: =Parameters!J12 -> 0.25 | E4: =Parameters!L12 -> 0.95 | F4: =표3[[#This Row],[Base Fee(Hype)]]*표3[[#This Row],[Multiplier (1 − wₙ · δ)]] -> 0.04275 | G4: ='GMV(Layer)'!V16/'GMV(Layer)'!V21 -> 0.71428571 | H4: =H5*표3[[#This Row],[F_L3]] -> 136800 | I4: 0.008 | J4: =표3[[#This Row],[Launch Count / mo]]*표3[[#This Row],[Graduation Ratio (θ)]] -> 1094.4 | K4: =표3[[#This Row],[Effective Fee (HYPE eqv.)]]*표3[[#This Row],[Graduation Count / mo]] -> 46.7856 | L4: =표3[[#This Row],[Monthly Fee (HYPE)]]*12 -> 561.4272 | M4: {=표3[[#This Row],[Monthly Fee (HYPE)]]*표5[$HYPE in USD]} -> 1871.424 | N4: =표3[[#This Row],[Monthly Fee (USD)]]*12 -> 22457.088 | O4: =표3[[#This Row],[Monthly Fee (USD)]]/1000000000 -> 1.871424e-06
A5: P3 | B5: 0.045 | C5: =Parameters!K13 -> 0.2 | D5: =Parameters!J13 -> 0.35 | E5: =Parameters!L13 -> 0.93 | F5: =표3[[#This Row],[Base Fee(Hype)]]*표3[[#This Row],[Multiplier (1 − wₙ · δ)]] -> 0.04185 | G5: ='GMV(Layer)'!V21/'GMV(Layer)'!V26 -> 0.93333333 | H5: =H6*표3[[#This Row],[F_L3]] -> 191520 | I5: 0.01 | J5: =표3[[#This Row],[Launch Count / mo]]*표3[[#This Row],[Graduation Ratio (θ)]] -> 1915.2 | K5: =표3[[#This Row],[Effective Fee (HYPE eqv.)]]*표3[[#This Row],[Graduation Count / mo]] -> 80.15112 | L5: =표3[[#This Row],[Monthly Fee (HYPE)]]*12 -> 961.81344 | M5: {=표3[[#This Row],[Monthly Fee (HYPE)]]*표5[$HYPE in USD]} -> 3206.0448 | N5: =표3[[#This Row],[Monthly Fee (USD)]]*12 -> 38472.538 | O5: =표3[[#This Row],[Monthly Fee (USD)]]/1000000000 -> 3.2060448e-06
A6: P4 | B6: 0.045 | C6: =Parameters!K14 -> 0.2 | D6: =Parameters!J14 -> 0.45 | E6: =Parameters!L14 -> 0.91 | F6: =표3[[#This Row],[Base Fee(Hype)]]*표3[[#This Row],[Multiplier (1 − wₙ · δ)]] -> 0.04095 | G6: ='GMV(Layer)'!V26/'GMV(Layer)'!V31 -> 1.1904762 | H6: =H7*표3[[#This Row],[F_L3]] -> 205200 | I6: 0.012 | J6: =표3[[#This Row],[Launch Count / mo]]*표3[[#This Row],[Graduation Ratio (θ)]] -> 2462.4 | K6: =표3[[#This Row],[Effective Fee (HYPE eqv.)]]*표3[[#This Row],[Graduation Count / mo]] -> 100.83528 | L6: =표3[[#This Row],[Monthly Fee (HYPE)]]*12 -> 1210.0234 | M6: {=표3[[#This Row],[Monthly Fee (HYPE)]]*표5[$HYPE in USD]} -> 4033.4112 | N6: =표3[[#This Row],[Monthly Fee (USD)]]*12 -> 48400.934 | O6: =표3[[#This Row],[Monthly Fee (USD)]]/1000000000 -> 4.0334112e-06
A7: P5 | B7: 0.045 | C7: =Parameters!K15 -> 0.2 | D7: =Parameters!J15 -> 0.6 | E7: =Parameters!L15 -> 0.88 | F7: =표3[[#This Row],[Base Fee(Hype)]]*표3[[#This Row],[Multiplier (1 − wₙ · δ)]] -> 0.0396 | G7: 1 | H7: 172368 | I7: 0.014 | J7: =표3[[#This Row],[Launch Count / mo]]*표3[[#This Row],[Graduation Ratio (θ)]] -> 2413.152 | K7: =표3[[#This Row],[Effective Fee (HYPE eqv.)]]*표3[[#This Row],[Graduation Count / mo]] -> 95.560819 | L7: =표3[[#This Row],[Monthly Fee (HYPE)]]*12 -> 1146.7298 | M7: {=표3[[#This Row],[Monthly Fee (HYPE)]]*표5[$HYPE in USD]} -> 3822.4328 | N7: =표3[[#This Row],[Monthly Fee (USD)]]*12 -> 45869.193 | O7: =표3[[#This Row],[Monthly Fee (USD)]]/1000000000 -> 3.8224328e-06

Sheet Rebalancing Fee
A1: Phase | B1: Layer | C1: AUM(B) | D1: R | F1: base_rate_year | G1: wₙ (Native Usage) | H1: eff_rate_year | I1: Annual Fee (B) | J1: Monthly Fee_layer (B) | L1: Phase | M1: Monthly Fee(B)
A2: P0 | B2: L1 | C2: =AUM!I2 -> 0.0057073078 | D2: 12 | E2: 0.001 | F2: =D2*E2 -> 0.012 | G2: =Parameters!J10 -> 0 | H2: =F2*(1-G2*Parameters!$K$10) -> 0.012 | I2: =C2*H2 -> 6.8487694e-05 | J2: =I2/12 -> 5.7073078e-06 | L2: P0 | M2: =SUM(J2:J4) -> 2.1246674e-05
B3: L2 | C3: =AUM!I3 -> 0.0071720151 | D3: 26 | E3: 0.001 | F3: =D3*E3 -> 0.026 | G3: =Parameters!J10 -> 0 | H3: =F3*(1-G3*Parameters!$K$10) -> 0.026 | I3: =C3*H3 -> 0.00018647239 | J3: =I3/12 -> 1.5539366e-05 | L3: P1 | M3: =SUM(J7:J9) -> 0.00012057284
B4: VS | C4: =AUM!I4 -> 0 | D4: 26 | E4: 0.001 | F4: =D4*E4 -> 0.026 | G4: =Parameters!J10 -> 0 | H4: =F4*(1-G4*Parameters!$K$10) -> 0.026 | I4: =C4*H4 -> 0 | J4: =I4/12 -> 0 | L4: P2 | M4: =SUM(J12:J14) -> 0.0003777624
B5: Partner | C5: =AUM!I5 -> 0.00038856603 | D5: - | E5: - | F5: - | G5: =Parameters!J10 -> 0 | H5: - | I5: - | J5: - | L5: P3 | M5: =SUM(J17:J19) -> 0.00064431016
B6: L3 | C6: =AUM!I6 -> 0.00055509432 | D6: - | E6: - | F6: - | G6: =Parameters!J10 -> 0 | H6: - | I6: - | J6: - | L6: P4 | M6: =SUM(J22:J24) -> 0.00090741185
A7: P1 | B7: L1 | C7: =AUM!I7 -> 0.045658463 | D7: 12 | E7: 0.001 | F7: =D7*E7 -> 0.012 | G7: =Parameters!J11 -> 0.15 | H7: =F7*(1-G7*Parameters!$K$10) -> 0.01164 | I7: =C7*H7 -> 0.0005314645 | J7: =I7/12 -> 4.4288709e-05 | L7: P5 | M7: =SUM(J27:J29) -> 0.0010150435
B8: L2 | C8: =AUM!I8 -> 0.035860076 | D8: 26 | E8: 0.001 | F8: =D8*E8 -> 0.026 | G8: =Parameters!J11 -> 0.15 | H8: =F8*(1-G8*Parameters!$K$10) -> 0.02522 | I8: =C8*H8 -> 0.00090439111 | J8: =I8/12 -> 7.5365926e-05
B9: VS | C9: =AUM!I9 -> 0.00043689364 | D9: 26 | E9: 0.001 | F9: =D9*E9 -> 0.026 | G9: =Parameters!J11 -> 0.15 | H9: =F9*(1-G9*Parameters!$K$10) -> 0.02522 | I9: =C9*H9 -> 1.1018458e-05 | J9: =I9/12 -> 9.1820481e-07
B10: Partner | C10: =AUM!I10 -> 0.00055509432 | D10: - | E10: - | F10: - | G10: =Parameters!J11 -> 0.15 | H10: - | I10: - | J10: -
B11: L3 | C11: =AUM!I11 -> 0.00055509432 | D11: 0 | E11: - | F11: - | G11: =Parameters!J11 -> 0.15 | H11: - | I11: - | J11: -
A12: P2 | B12: L1 | C12: =AUM!I12 -> 0.16751659 | D12: 12 | E12: 0.001 | F12: =D12*E12 -> 0.012 | G12: =표2[[#This Row],[wₙ (Native Usage)]] -> 0.25 | H12: =F12*(1-G12*Parameters!$K$10) -> 0.0114 | I12: =C12*H12 -> 0.0019096892 | J12: =I12/12 -> 0.00015914076
B13: L2 | C13: =AUM!I13 -> 0.10408431 | D13: 26 | E13: 0.001 | F13: =D13*E13 -> 0.026 | G13: =G12 -> 0.25 | H13: =F13*(1-G13*Parameters!$K$10) -> 0.0247 | I13: =C13*H13 -> 0.0025708826 | J13: =I13/12 -> 0.00021424021
B14: VS | C14: =AUM!I14 -> 0.0021286248 | D14: 26 | E14: 0.001 | F14: =D14*E14 -> 0.026 | G14: =G13 -> 0.25 | H14: =F14*(1-G14*Parameters!$K$10) -> 0.0247 | I14: =C14*H14 -> 5.2577032e-05 | J14: =I14/12 -> 4.3814193e-06
B15: Partner | C15: =AUM!I15 -> 0.0013189041 | D15: - | E15: - | F15: - | G15: =G14 -> 0.25 | H15: - | I15: - | J15: -
B16: L3 | C16: =AUM!I16 -> 0.0013189041 | D16: - | E16: - | F16: - | G16: =G15 -> 0.25 | H16: - | I16: - | J16: -
A17: P3 | B17: L1 | C17: =AUM!I17 -> 0.32621733 | D17: 12 | E17: 0.001 | F17: =D17*E17 -> 0.012 | G17: =Parameters!J13 -> 0.35 | H17: =F17*(1-G17*Parameters!$K$10) -> 0.01116 | I17: =C17*H17 -> 0.0036405854 | J17: =I17/12 -> 0.00030338212
B18: L2 | C18: =AUM!I18 -> 0.16472986 | D18: 26 | E18: 0.001 | F18: =D18*E18 -> 0.026 | G18: =G17 -> 0.35 | H18: =F18*(1-G18*Parameters!$K$10) -> 0.02418 | I18: =C18*H18 -> 0.0039831681 | J18: =I18/12 -> 0.00033193067
B19: VS | C19: =AUM!I19 -> 0.0044651969 | D19: 26 | E19: 0.001 | F19: =D19*E19 -> 0.026 | G19: =G18 -> 0.35 | H19: =F19*(1-G19*Parameters!$K$10) -> 0.02418 | I19: =C19*H19 -> 0.00010796846 | J19: =I19/12 -> 8.9973718e-06
B20: Partner | C20: =AUM!I20 -> 0.0018464658 | D20: - | E20: - | F20: - | G20: =G19 -> 0.35 | H20: - | I20: - | J20: -
B21: L3 | C21: =AUM!I21 -> 0.0018464658 | D21: - | E21: - | F21: - | G21: =G20 -> 0.35 | H21: - | I21: - | J21: -
A22: P4 | B22: L1 | C22: =AUM!I22 -> 0.51122124 | D22: 12 | E22: 0.001 | F22: =D22*E22 -> 0.012 | G22: =Parameters!J14 -> 0.45 | H22: =F22*(1-G22*Parameters!$K$10) -> 0.01092 | I22: =C22*H22 -> 0.0055825359 | J22: =I22/12 -> 0.00046521133
B23: L2 | C23: =AUM!I23 -> 0.21682359 | D23: 26 | E23: 0.001 | F23: =D23*E23 -> 0.026 | G23: =G22 -> 0.45 | H23: =F23*(1-G23*Parameters!$K$10) -> 0.02366 | I23: =C23*H23 -> 0.0051300462 | J23: =I23/12 -> 0.00042750385
B24: VS | C24: =AUM!I24 -> 0.0074539355 | D24: 26 | E24: 0.001 | F24: =D24*E24 -> 0.026 | G24: =G23 -> 0.45 | H24: =F24*(1-G24*Parameters!$K$10) -> 0.02366 | I24: =C24*H24 -> 0.00017636011 | J24: =I24/12 -> 1.4696676e-05
B25: Partner | C25: =AUM!I25 -> 0.0019783562 | D25: - | E25: - | F25: - | G25: =G24 -> 0.45 | H25: - | I25: - | J25: -
B26: L3 | C26: =AUM!I26 -> 0.0019783562 | D26: - | E26: - | F26: - | G26: =G25 -> 0.45 | H26: - | I26: - | J26: -
A27: P5 | B27: L1 | C27: =AUM!I27 -> 0.5942065 | D27: 12 | E27: 0.001 | F27: =D27*E27 -> 0.012 | G27: =Parameters!J15 -> 0.6 | H27: =F27*(1-G27*Parameters!$K$10) -> 0.01056 | I27: =C27*H27 -> 0.0062748206 | J27: =I27/12 -> 0.00052290172
B28: L2 | C28: =AUM!I28 -> 0.2494018 | D28: 26 | E28: 0.001 | F28: =D28*E28 -> 0.026 | G28: =G27 -> 0.6 | H28: =F28*(1-G28*Parameters!$K$10) -> 0.02288 | I28: =C28*H28 -> 0.0057063132 | J28: =I28/12 -> 0.0004755261
B29: VS | C29: =AUM!I29 -> 0.0087145275 | D29: 26 | E29: 0.001 | F29: =D29*E29 -> 0.026 | G29: =G28 -> 0.6 | H29: =F29*(1-G29*Parameters!$K$10) -> 0.02288 | I29: =C29*H29 -> 0.00019938839 | J29: =I29/12 -> 1.6615699e-05
B30: Partner | C30: =AUM!I30 -> 0.00094961096 | D30: - | E30: - | F30: - | G30: =G29 -> 0.6 | H30: - | I30: - | J30: -
B31: L3 | C31: =AUM!I31 -> 0.0016618192 | D31: - | E31: - | F31: - | G31: =G30 -> 0.6 | H31: - | I31: - | J31: -

Sheet Management Fee
A1: Phase | B1: Layer | C1: AUM(B) | E1: wₙ (Native Usage) | F1: eff_rate_year | G1: Annual Fee (B) | H1: Monthly Fee_layer (B) | J1: Phase | K1: 열1
A2: P0 | B2: L1 | C2: =AUM!I2 -> 0.0057073078 | D2: 0.007 | E2: 0 | F2: =D2*(1-E2*Parameters!$K$10) -> 0.007 | G2: =F2*C2 -> 3.9951155e-05 | H2: =G2/12 -> 3.3292629e-06 | J2: P0 | K2: =SUM(H2:H6) -> 8.9645346e-06
B3: L2 | C3: =AUM!I3 -> 0.0071720151 | D3: 0.0085 | E3: 0 | F3: =D3*(1-E3*Parameters!$K$10) -> 0.0085 | G3: =F3*C3 -> 6.0962129e-05 | H3: =G3/12 -> 5.0801774e-06 | J3: P1 | K3: =SUM(H7:H11) -> 5.1500148e-05
B4: VS | C4: =AUM!I4 -> 0 | D4: 0.01 | E4: 0 | F4: =D4*(1-E4*Parameters!$K$10) -> 0.01 | G4: =F4*C4 -> 0 | H4: =G4/12 -> 0 | J4: P2 | K4: =SUM(H12:H16) -> 0.00016612354
B5: Partner | C5: =AUM!I5 -> 0.00038856603 | D5: 0.01 | E5: 0 | F5: =D5*(1-E5*Parameters!$K$10) -> 0.01 | G5: =F5*C5 -> 3.8856603e-06 | H5: =G5/12 -> 3.2380502e-07 | J5: P3 | K5: =SUM(H17:H21) -> 0.00029109574
B6: L3 | C6: =AUM!I6 -> 0.00055509432 | D6: 0.005 | E6: 0 | F6: =D6*(1-E6*Parameters!$K$10) -> 0.005 | G6: =F6*C6 -> 2.7754716e-06 | H6: =G6/12 -> 2.312893e-07 | J6: P4 | K6: =SUM(H22:H26) -> 0.0004190371
A7: P1 | B7: L1 | C7: =AUM!I7 -> 0.045658463 | D7: 0.007 | E7: 0.15 | F7: =D7*(1-E7*Parameters!$K$10) -> 0.00679 | G7: =F7*C7 -> 0.00031002096 | H7: =G7/12 -> 2.583508e-05 | J7: P5 | K7: =SUM(H27:H31) -> 0.00046818283
B8: L2 | C8: =AUM!I8 -> 0.035860076 | D8: 0.0085 | E8: 0.15 | F8: =D8*(1-E8*Parameters!$K$10) -> 0.008245 | G8: =F8*C8 -> 0.00029566632 | H8: =G8/12 -> 2.463886e-05
B9: VS | C9: =AUM!I9 -> 0.00043689364 | D9: 0.01 | E9: 0.15 | F9: =D9*(1-E9*Parameters!$K$10) -> 0.0097 | G9: =F9*C9 -> 4.2378684e-06 | H9: =G9/12 -> 3.531557e-07
B10: Partner | C10: =AUM!I10 -> 0.00055509432 | D10: 0.01 | E10: 0.15 | F10: =D10*(1-E10*Parameters!$K$10) -> 0.0097 | G10: =F10*C10 -> 5.3844149e-06 | H10: =G10/12 -> 4.4870124e-07
B11: L3 | C11: =AUM!I11 -> 0.00055509432 | D11: 0.005 | E11: 0.15 | F11: =D11*(1-E11*Parameters!$K$10) -> 0.00485 | G11: =F11*C11 -> 2.6922075e-06 | H11: =G11/12 -> 2.2435062e-07
A12: P2 | B12: L1 | C12: =AUM!I12 -> 0.16751659 | D12: 0.007 | E12: 0.25 | F12: =D12*(1-E12*Parameters!$K$10) -> 0.00665 | G12: =F12*C12 -> 0.0011139853 | H12: =G12/12 -> 9.2832112e-05
B13: L2 | C13: =AUM!I13 -> 0.10408431 | D13: 0.0085 | E13: 0.25 | F13: =D13*(1-E13*Parameters!$K$10) -> 0.008075 | G13: =F13*C13 -> 0.00084048084 | H13: =G13/12 -> 7.004007e-05
B14: VS | C14: =AUM!I14 -> 0.0021286248 | D14: 0.01 | E14: 0.25 | F14: =D14*(1-E14*Parameters!$K$10) -> 0.0095 | G14: =F14*C14 -> 2.0221935e-05 | H14: =G14/12 -> 1.6851613e-06
B15: Partner | C15: =AUM!I15 -> 0.0013189041 | D15: 0.01 | E15: 0.25 | F15: =D15*(1-E15*Parameters!$K$10) -> 0.0095 | G15: =F15*C15 -> 1.2529589e-05 | H15: =G15/12 -> 1.0441324e-06
B16: L3 | C16: =AUM!I16 -> 0.0013189041 | D16: 0.005 | E16: 0.25 | F16: =D16*(1-E16*Parameters!$K$10) -> 0.00475 | G16: =F16*C16 -> 6.2647945e-06 | H16: =G16/12 -> 5.2206621e-07
A17: P3 | B17: L1 | C17: =AUM!I17 -> 0.32621733 | D17: 0.007 | E17: 0.35 | F17: =D17*(1-E17*Parameters!$K$10) -> 0.00651 | G17: =F17*C17 -> 0.0021236748 | H17: =G17/12 -> 0.0001769729
B18: L2 | C18: =AUM!I18 -> 0.16472986 | D18: 0.0085 | E18: 0.35 | F18: =D18*(1-E18*Parameters!$K$10) -> 0.007905 | G18: =F18*C18 -> 0.0013021896 | H18: =G18/12 -> 0.0001085158
B19: VS | C19: =AUM!I19 -> 0.0044651969 | D19: 0.01 | E19: 0.35 | F19: =D19*(1-E19*Parameters!$K$10) -> 0.0093 | G19: =F19*C19 -> 4.1526331e-05 | H19: =G19/12 -> 3.4605276e-06
B20: Partner | C20: =AUM!I20 -> 0.0018464658 | D20: 0.01 | E20: 0.35 | F20: =D20*(1-E20*Parameters!$K$10) -> 0.0093 | G20: =F20*C20 -> 1.7172132e-05 | H20: =G20/12 -> 1.431011e-06
B21: L3 | C21: =AUM!I21 -> 0.0018464658 | D21: 0.005 | E21: 0.35 | F21: =D21*(1-E21*Parameters!$K$10) -> 0.00465 | G21: =F21*C21 -> 8.5860658e-06 | H21: =G21/12 -> 7.1550548e-07
A22: P4 | B22: L1 | C22: =AUM!I22 -> 0.51122124 | D22: 0.007 | E22: 0.45 | F22: =D22*(1-E22*Parameters!$K$10) -> 0.00637 | G22: =F22*C22 -> 0.0032564793 | H22: =G22/12 -> 0.00027137327
B23: L2 | C23: =AUM!I23 -> 0.21682359 | D23: 0.0085 | E23: 0.45 | F23: =D23*(1-E23*Parameters!$K$10) -> 0.007735 | G23: =F23*C23 -> 0.0016771305 | H23: =G23/12 -> 0.00013976087
B24: VS | C24: =AUM!I24 -> 0.0074539355 | D24: 0.01 | E24: 0.45 | F24: =D24*(1-E24*Parameters!$K$10) -> 0.0091 | G24: =F24*C24 -> 6.7830813e-05 | H24: =G24/12 -> 5.6525677e-06
B25: Partner | C25: =AUM!I25 -> 0.0019783562 | D25: 0.01 | E25: 0.45 | F25: =D25*(1-E25*Parameters!$K$10) -> 0.0091 | G25: =F25*C25 -> 1.8003041e-05 | H25: =G25/12 -> 1.5002534e-06
B26: L3 | C26: =AUM!I26 -> 0.0019783562 | D26: 0.005 | E26: 0.45 | F26: =D26*(1-E26*Parameters!$K$10) -> 0.00455 | G26: =F26*C26 -> 9.0015205e-06 | H26: =G26/12 -> 7.5012671e-07
A27: P5 | B27: L1 | C27: =AUM!I27 -> 0.5942065 | D27: 0.007 | E27: 0.6 | F27: =D27*(1-E27*Parameters!$K$10) -> 0.00616 | G27: =F27*C27 -> 0.003660312 | H27: =G27/12 -> 0.000305026
B28: L2 | C28: =AUM!I28 -> 0.2494018 | D28: 0.0085 | E28: 0.6 | F28: =D28*(1-E28*Parameters!$K$10) -> 0.00748 | G28: =F28*C28 -> 0.0018655255 | H28: =G28/12 -> 0.00015546046
B29: VS | C29: =AUM!I29 -> 0.0087145275 | D29: 0.01 | E29: 0.6 | F29: =D29*(1-E29*Parameters!$K$10) -> 0.0088 | G29: =F29*C29 -> 7.6687842e-05 | H29: =G29/12 -> 6.3906535e-06
B30: Partner | C30: =AUM!I30 -> 0.00094961096 | D30: 0.01 | E30: 0.6 | F30: =D30*(1-E30*Parameters!$K$10) -> 0.0088 | G30: =F30*C30 -> 8.3565764e-06 | H30: =G30/12 -> 6.9638137e-07
B31: L3 | C31: =AUM!I31 -> 0.0016618192 | D31: 0.005 | E31: 0.6 | F31: =D31*(1-E31*Parameters!$K$10) -> 0.0044 | G31: =F31*C31 -> 7.3120044e-06 | H31: =G31/12 -> 6.093337e-07

Sheet Protocol Fee(Trade)
A1: Phase | B1: VIP0_share | C1: VIP1_share | D1: VIP2_share | E1: VIP3_share | F1: VIP4_share | G1: Blended_Fee_rate | H1: wₙ (Native Usage) | I1: eff_fee | J1: f_partner | K1: f_canonical | L1: GMV_trade(B) | M1: GMV_Canonical | N1: GMV_internal(B) | O1: GMV_partner(B) | P1: Monthly Protocol Fee(B) | Q1: Annual Protocol Fee(B)
